Workbook

Sheet Sonde étalon
B2: N° Certificat | C2: E18LM2664
B4: Date du certificat: | C4: 43229
B6: Désignation de la chaine | C6: SPY REF REF 1V + PT100
B8: Résolution | C8: 0,01°C
B10: Point d'étalonnage | C10: Erreur de justesse | D10: U(K=2)
B11: -80°C | C11: -0.14 | D11: 0.17
B12: -20°C | C12: 0 | D12: 0.08
B13: 5°C | C13: -0.17 | D13: 0.08
B14: 20°C | C14: -0.17 | D14: 0.08
B17: Sondes DS18B20
B18: Résolution sur 12 bits | C18: 0,0625 °C
B33: Sonde DHT11
B34: Résolution sur 8 bits | C34: 1°C

Sheet Relevés -20°C
B1: RELEVES | N1: REFERENCE | R1: ERREURS DE JUSTESSE | AC1: RELEVES CORRIGES | AN1: ECARTS
AB2: NB | AC2: =COUNTA(AC6:AC4994) -> 120 | AD2: =COUNTA(AD6:AD4994) -> 120 | AE2: =COUNTA(AE6:AE4994) -> 120 | AF2: =COUNTA(AF6:AF4994) -> 120 | AG2: =COUNTA(AG6:AG4994) -> 120 | AH2: =COUNTA(AH6:AH4994) -> 120 | AI2: =COUNTA(AI6:AI4994) -> 120 | AJ2: =COUNTA(AJ6:AJ4994) -> 120 | AK2: =COUNTA(AK6:AK4994) -> 120 | AM2: NB | AN2: =COUNTA(AN6:AN4994) -> 120 | AO2: =COUNTA(AO6:AO4994) -> 120 | AP2: =COUNTA(AP6:AP4994) -> 120 | AQ2: =COUNTA(AQ6:AQ4994) -> 120 | AR2: =COUNTA(AR6:AR4994) -> 120 | AS2: =COUNTA(AS6:AS4994) -> 120 | AT2: =COUNTA(AT6:AT4994) -> 120 | AU2: =COUNTA(AU6:AU4994) -> 120 | AV2: =COUNTA(AV6:AV4994) -> 120
Q3: Erreur Justesse | R3: =AVERAGE(R6:R4994) -> -0.077416667 | S3: =AVERAGE(S6:S4994) -> -0.086833333 | T3: =AVERAGE(T6:T4994) -> 0.0205 | U3: =AVERAGE(U6:U4994) -> -0.023833333 | V3: =AVERAGE(V6:V4994) -> -0.16258333 | W3: =AVERAGE(W6:W4994) -> -0.16816667 | X3: =AVERAGE(X6:X4994) -> 0.22208333 | Y3: =AVERAGE(Y6:Y4994) -> 0.155 | Z3: =AVERAGE(Z6:Z4994) -> -0.3185 | AB3: Ecart type | AC3: =STDEV(AC6:AC4994) -> 0.2385453 | AD3: =STDEV(AD6:AD4994) -> 0.2456179 | AE3: =STDEV(AE6:AE4994) -> 0.24803423 | AF3: =STDEV(AF6:AF4994) -> 0.24471506 | AG3: =STDEV(AG6:AG4994) -> 0.23533156 | AH3: =STDEV(AH6:AH4994) -> 0.23560822 | AI3: =STDEV(AI6:AI4994) -> 0.2431405 | AJ3: =STDEV(AJ6:AJ4994) -> 0.23911157 | AK3: =STDEV(AK6:AK4994) -> 0.24118957 | AM3: Ecart type | AN3: =STDEV(AN6:AN4994) -> 0.024305335 | AO3: =STDEV(AO6:AO4994) -> 0.020497318 | AP3: =STDEV(AP6:AP4994) -> 0.023112803 | AQ3: =STDEV(AQ6:AQ4994) -> 0.019454033 | AR3: =STDEV(AR6:AR4994) -> 0.02143961 | AS3: =STDEV(AS6:AS4994) -> 0.023656624 | AT3: =STDEV(AT6:AT4994) -> 0.022111096 | AU3: =STDEV(AU6:AU4994) -> 0.021302148 | AV3: =STDEV(AV6:AV4994) -> 0.022291047
R4: =STDEV(R6:R4994) -> 0.024305335 | S4: =STDEV(S6:S4994) -> 0.020497318 | T4: =STDEV(T6:T4994) -> 0.023112803 | U4: =STDEV(U6:U4994) -> 0.019454033 | V4: =STDEV(V6:V4994) -> 0.02143961 | W4: =STDEV(W6:W4994) -> 0.023656624 | X4: =STDEV(X6:X4994) -> 0.022111096 | Y4: =STDEV(Y6:Y4994) -> 0.021302148 | Z4: =STDEV(Z6:Z4994) -> 0.022291047 | AB4: Incertitude | AC4: =SQRT((AC3/SQRT(AC2))^2+(('Sonde étalon'!$D$13)/2)^2+(0.0625/(2*SQRT(3)))^2+(0.001/(2*SQRT(3)))^2) -> 0.048987784 | AD4: =SQRT((AD3/SQRT(AD2))^2+(('Sonde étalon'!$D$13)/2)^2+(0.0625/(2*SQRT(3)))^2+(0.001/(2*SQRT(3)))^2) -> 0.049278177 | AE4: =SQRT((AE3/SQRT(AE2))^2+(('Sonde étalon'!$D$13)/2)^2+(0.0625/(2*SQRT(3)))^2+(0.001/(2*SQRT(3)))^2) -> 0.049378933 | AF4: =SQRT((AF3/SQRT(AF2))^2+(('Sonde étalon'!$D$13)/2)^2+(0.0625/(2*SQRT(3)))^2+(0.001/(2*SQRT(3)))^2) -> 0.049240732 | AG4: =SQRT((AG3/SQRT(AG2))^2+(('Sonde étalon'!$D$13)/2)^2+(0.0625/(2*SQRT(3)))^2+(0.001/(2*SQRT(3)))^2) -> 0.048858081 | AH4: =SQRT((AH3/SQRT(AH2))^2+(('Sonde étalon'!$D$13)/2)^2+(0.0625/(2*SQRT(3)))^2+(0.001/(2*SQRT(3)))^2) -> 0.04886919 | AI4: =SQRT((AI3/SQRT(AI2))^2+(('Sonde étalon'!$D$13)/2)^2+(0.0625/(2*SQRT(3)))^2+(0.001/(2*SQRT(3)))^2) -> 0.049175689 | AJ4: =SQRT((AJ3/SQRT(AJ2))^2+(('Sonde étalon'!$D$13)/2)^2+(0.0625/(2*SQRT(3)))^2+(0.001/(2*SQRT(3)))^2) -> 0.049010785 | AK4: =SQRT((AK3/SQRT(AK2))^2+(('Sonde étalon'!$D$13)/2)^2+(0.0625/(2*SQRT(3)))^2+(0.001/(2*SQRT(3)))^2) -> 0.049095562 | AM4: Incertitude | AN4: =SQRT((AN3/SQRT(AN2))^2+(('Sonde étalon'!$D$12)/2)^2+(0.0625/(2*SQRT(3)))^2+(0.01/(2*SQRT(3)))^2) -> 0.044031546 | AO4: =SQRT((AO3/SQRT(AO2))^2+(('Sonde étalon'!$D$12)/2)^2+(0.0625/(2*SQRT(3)))^2+(0.01/(2*SQRT(3)))^2) -> 0.044015399 | AP4: =SQRT((AP3/SQRT(AP2))^2+(('Sonde étalon'!$D$12)/2)^2+(0.0625/(2*SQRT(3)))^2+(0.01/(2*SQRT(3)))^2) -> 0.044026195 | AQ4: =SQRT((AQ3/SQRT(AQ2))^2+(('Sonde étalon'!$D$12)/2)^2+(0.0625/(2*SQRT(3)))^2+(0.01/(2*SQRT(3)))^2) -> 0.044011453 | AR4: =SQRT((AR3/SQRT(AR2))^2+(('Sonde étalon'!$D$12)/2)^2+(0.0625/(2*SQRT(3)))^2+(0.01/(2*SQRT(3)))^2) -> 0.044019139 | AS4: =SQRT((AS3/SQRT(AS2))^2+(('Sonde étalon'!$D$12)/2)^2+(0.0625/(2*SQRT(3)))^2+(0.01/(2*SQRT(3)))^2) -> 0.044028602 | AT4: =SQRT((AT3/SQRT(AT2))^2+(('Sonde étalon'!$D$12)/2)^2+(0.0625/(2*SQRT(3)))^2+(0.01/(2*SQRT(3)))^2) -> 0.044021907 | AU4: =SQRT((AU3/SQRT(AU2))^2+(('Sonde étalon'!$D$12)/2)^2+(0.0625/(2*SQRT(3)))^2+(0.01/(2*SQRT(3)))^2) -> 0.044018583 | AV4: =SQRT((AV3/SQRT(AV2))^2+(('Sonde étalon'!$D$12)/2)^2+(0.0625/(2*SQRT(3)))^2+(0.01/(2*SQRT(3)))^2) -> 0.044022664
A5: Counter | B5: Date | C5: Time | D5: MIL | E5: HGAV | F5: HGAR | G5: HDAV | H5: HDAR | I5: BGAV | J5: BGAR | K5: BDAV | L5: BDAR | N5: Ref | O5: Ref corrigée | R5: MIL | S5: HGAV | T5: HGAR | U5: HDAV | V5: HDAR | W5: BGAV | X5: BGAR | Y5: BDAV | Z5: BDAR | AC5: MIL | AD5: HGAV | AE5: HGAR | AF5: HDAV | AG5: HDAR | AH5: BGAV | AI5: BGAR | AJ5: BDAV | AK5: BDAR | AN5: MIL | AO5: HGAV | AP5: HGAR | AQ5: HDAV | AR5: HDAR | AS5: BGAV | AT5: BGAR | AU5: BDAV | AV5: BDAR
A6: 12 | B6: 43581 | C6: 0.41711806 | D6: -20.63 | E6: -20.56 | F6: -20.44 | G6: -20.5 | H6: -20.69 | I6: -20.69 | J6: -20.25 | K6: -20.31 | L6: -20.81 | M6: 24.8 | N6: -20.49 | O6: =N6-'Sonde étalon'!$C$12 -> -20.49 | R6: =D6-O6 -> -0.14 | S6: =E6-O6 -> -0.07 | T6: =F6-O6 -> 0.05 | U6: =G6-O6 -> -0.01 | V6: =H6-O6 -> -0.2 | W6: =I6-O6 -> -0.2 | X6: =J6-O6 -> 0.24 | Y6: =K6-O6 -> 0.18 | Z6: =L6-O6 -> -0.32 | AC6: =D6-$R$3 -> -20.552583 | AD6: =E6-$S$3 -> -20.473167 | AE6: =F6-$T$3 -> -20.4605 | AF6: =G6-$U$3 -> -20.476167 | AG6: =H6-$V$3 -> -20.527417 | AH6: =I6-$W$3 -> -20.521833 | AI6: =J6-$X$3 -> -20.472083 | AJ6: =K6-$Y$3 -> -20.465 | AK6: =L6-$Z$3 -> -20.4915 | AN6: =AC6-O6 -> -0.062583333 | AO6: =AD6-O6 -> 0.016833333 | AP6: =AE6-O6 -> 0.0295 | AQ6: =AF6-O6 -> 0.013833333 | AR6: =AG6-O6 -> -0.037416667 | AS6: =AH6-O6 -> -0.031833333 | AT6: =AI6-O6 -> 0.017916667 | AU6: =AJ6-O6 -> 0.025 | AV6: =AK6-O6 -> -0.0015
A7: 13 | B7: 43581 | C7: 0.4178125 | D7: -20.63 | E7: -20.63 | F7: -20.56 | G7: -20.56 | H7: -20.75 | I7: -20.75 | J7: -20.31 | K7: -20.44 | L7: -20.88 | M7: 24.8 | N7: -20.57 | O7: =N7-'Sonde étalon'!$C$12 -> -20.57 | R7: =D7-O7 -> -0.06 | S7: =E7-O7 -> -0.06 | T7: =F7-O7 -> 0.01 | U7: =G7-O7 -> 0.01 | V7: =H7-O7 -> -0.18 | W7: =I7-O7 -> -0.18 | X7: =J7-O7 -> 0.26 | Y7: =K7-O7 -> 0.13 | Z7: =L7-O7 -> -0.31 | AC7: =D7-$R$3 -> -20.552583 | AD7: =E7-$S$3 -> -20.543167 | AE7: =F7-$T$3 -> -20.5805 | AF7: =G7-$U$3 -> -20.536167 | AG7: =H7-$V$3 -> -20.587417 | AH7: =I7-$W$3 -> -20.581833 | AI7: =J7-$X$3 -> -20.532083 | AJ7: =K7-$Y$3 -> -20.595 | AK7: =L7-$Z$3 -> -20.5615 | AN7: =AC7-O7 -> 0.017416667 | AO7: =AD7-O7 -> 0.026833333 | AP7: =AE7-O7 -> -0.0105 | AQ7: =AF7-O7 -> 0.033833333 | AR7: =AG7-O7 -> -0.017416667 | AS7: =AH7-O7 -> -0.011833333 | AT7: =AI7-O7 -> 0.037916667 | AU7: =AJ7-O7 -> -0.025 | AV7: =AK7-O7 -> 0.0085
A8: 14 | B8: 43581 | C8: 0.41850694 | D8: -20.69 | E8: -20.69 | F8: -20.56 | G8: -20.63 | H8: -20.81 | I8: -20.81 | J8: -20.38 | K8: -20.5 | L8: -20.94 | M8: 24.8 | N8: -20.63 | O8: =N8-'Sonde étalon'!$C$12 -> -20.63 | R8: =D8-O8 -> -0.06 | S8: =E8-O8 -> -0.06 | T8: =F8-O8 -> 0.07 | U8: =G8-O8 -> 0 | V8: =H8-O8 -> -0.18 | W8: =I8-O8 -> -0.18 | X8: =J8-O8 -> 0.25 | Y8: =K8-O8 -> 0.13 | Z8: =L8-O8 -> -0.31 | AC8: =D8-$R$3 -> -20.612583 | AD8: =E8-$S$3 -> -20.603167 | AE8: =F8-$T$3 -> -20.5805 | AF8: =G8-$U$3 -> -20.606167 | AG8: =H8-$V$3 -> -20.647417 | AH8: =I8-$W$3 -> -20.641833 | AI8: =J8-$X$3 -> -20.602083 | AJ8: =K8-$Y$3 -> -20.655 | AK8: =L8-$Z$3 -> -20.6215 | AN8: =AC8-O8 -> 0.017416667 | AO8: =AD8-O8 -> 0.026833333 | AP8: =AE8-O8 -> 0.0495 | AQ8: =AF8-O8 -> 0.023833333 | AR8: =AG8-O8 -> -0.017416667 | AS8: =AH8-O8 -> -0.011833333 | AT8: =AI8-O8 -> 0.027916667 | AU8: =AJ8-O8 -> -0.025 | AV8: =AK8-O8 -> 0.0085
A9: 15 | B9: 43581 | C9: 0.41920139 | D9: -20.75 | E9: -20.75 | F9: -20.63 | G9: -20.69 | H9: -20.88 | I9: -20.88 | J9: -20.44 | K9: -20.56 | L9: -21 | M9: 24.8 | N9: -20.69 | O9: =N9-'Sonde étalon'!$C$12 -> -20.69 | R9: =D9-O9 -> -0.06 | S9: =E9-O9 -> -0.06 | T9: =F9-O9 -> 0.06 | U9: =G9-O9 -> 0 | V9: =H9-O9 -> -0.19 | W9: =I9-O9 -> -0.19 | X9: =J9-O9 -> 0.25 | Y9: =K9-O9 -> 0.13 | Z9: =L9-O9 -> -0.31 | AC9: =D9-$R$3 -> -20.672583 | AD9: =E9-$S$3 -> -20.663167 | AE9: =F9-$T$3 -> -20.6505 | AF9: =G9-$U$3 -> -20.666167 | AG9: =H9-$V$3 -> -20.717417 | AH9: =I9-$W$3 -> -20.711833 | AI9: =J9-$X$3 -> -20.662083 | AJ9: =K9-$Y$3 -> -20.715 | AK9: =L9-$Z$3 -> -20.6815 | AN9: =AC9-O9 -> 0.017416667 | AO9: =AD9-O9 -> 0.026833333 | AP9: =AE9-O9 -> 0.0395 | AQ9: =AF9-O9 -> 0.023833333 | AR9: =AG9-O9 -> -0.027416667 | AS9: =AH9-O9 -> -0.021833333 | AT9: =AI9-O9 -> 0.027916667 | AU9: =AJ9-O9 -> -0.025 | AV9: =AK9-O9 -> 0.0085
A10: 16 | B10: 43581 | C10: 0.41989583 | D10: -20.81 | E10: -20.81 | F10: -20.69 | G10: -20.75 | H10: -20.94 | I10: -20.94 | J10: -20.5 | K10: -20.56 | L10: -21.06 | M10: 24.8 | N10: -20.74 | O10: =N10-'Sonde étalon'!$C$12 -> -20.74 | R10: =D10-O10 -> -0.07 | S10: =E10-O10 -> -0.07 | T10: =F10-O10 -> 0.05 | U10: =G10-O10 -> -0.01 | V10: =H10-O10 -> -0.2 | W10: =I10-O10 -> -0.2 | X10: =J10-O10 -> 0.24 | Y10: =K10-O10 -> 0.18 | Z10: =L10-O10 -> -0.32 | AC10: =D10-$R$3 -> -20.732583 | AD10: =E10-$S$3 -> -20.723167 | AE10: =F10-$T$3 -> -20.7105 | AF10: =G10-$U$3 -> -20.726167 | AG10: =H10-$V$3 -> -20.777417 | AH10: =I10-$W$3 -> -20.771833 | AI10: =J10-$X$3 -> -20.722083 | AJ10: =K10-$Y$3 -> -20.715 | AK10: =L10-$Z$3 -> -20.7415 | AN10: =AC10-O10 -> 0.0074166667 | AO10: =AD10-O10 -> 0.016833333 | AP10: =AE10-O10 -> 0.0295 | AQ10: =AF10-O10 -> 0.013833333 | AR10: =AG10-O10 -> -0.037416667 | AS10: =AH10-O10 -> -0.031833333 | AT10: =AI10-O10 -> 0.017916667 | AU10: =AJ10-O10 -> 0.025 | AV10: =AK10-O10 -> -0.0015
A11: 17 | B11: 43581 | C11: 0.42059028 | D11: -20.88 | E11: -20.88 | F11: -20.75 | G11: -20.81 | H11: -20.94 | I11: -20.94 | J11: -20.56 | K11: -20.63 | L11: -21.13 | M11: 24.8 | N11: -20.77 | O11: =N11-'Sonde étalon'!$C$12 -> -20.77 | R11: =D11-O11 -> -0.11 | S11: =E11-O11 -> -0.11 | T11: =F11-O11 -> 0.02 | U11: =G11-O11 -> -0.04 | V11: =H11-O11 -> -0.17 | W11: =I11-O11 -> -0.17 | X11: =J11-O11 -> 0.21 | Y11: =K11-O11 -> 0.14 | Z11: =L11-O11 -> -0.36 | AC11: =D11-$R$3 -> -20.802583 | AD11: =E11-$S$3 -> -20.793167 | AE11: =F11-$T$3 -> -20.7705 | AF11: =G11-$U$3 -> -20.786167 | AG11: =H11-$V$3 -> -20.777417 | AH11: =I11-$W$3 -> -20.771833 | AI11: =J11-$X$3 -> -20.782083 | AJ11: =K11-$Y$3 -> -20.785 | AK11: =L11-$Z$3 -> -20.8115 | AN11: =AC11-O11 -> -0.032583333 | AO11: =AD11-O11 -> -0.023166667 | AP11: =AE11-O11 -> -0.0005 | AQ11: =AF11-O11 -> -0.016166667 | AR11: =AG11-O11 -> -0.0074166667 | AS11: =AH11-O11 -> -0.0018333333 | AT11: =AI11-O11 -> -0.012083333 | AU11: =AJ11-O11 -> -0.015 | AV11: =AK11-O11 -> -0.0415
A12: 18 | B12: 43581 | C12: 0.42128472 | D12: -20.88 | E12: -20.88 | F12: -20.75 | G12: -20.81 | H12: -21 | I12: -21 | J12: -20.63 | K12: -20.69 | L12: -21.13 | M12: 24.8 | N12: -20.81 | O12: =N12-'Sonde étalon'!$C$12 -> -20.81 | R12: =D12-O12 -> -0.07 | S12: =E12-O12 -> -0.07 | T12: =F12-O12 -> 0.06 | U12: =G12-O12 -> 0 | V12: =H12-O12 -> -0.19 | W12: =I12-O12 -> -0.19 | X12: =J12-O12 -> 0.18 | Y12: =K12-O12 -> 0.12 | Z12: =L12-O12 -> -0.32 | AC12: =D12-$R$3 -> -20.802583 | AD12: =E12-$S$3 -> -20.793167 | AE12: =F12-$T$3 -> -20.7705 | AF12: =G12-$U$3 -> -20.786167 | AG12: =H12-$V$3 -> -20.837417 | AH12: =I12-$W$3 -> -20.831833 | AI12: =J12-$X$3 -> -20.852083 | AJ12: =K12-$Y$3 -> -20.845 | AK12: =L12-$Z$3 -> -20.8115 | AN12: =AC12-O12 -> 0.0074166667 | AO12: =AD12-O12 -> 0.016833333 | AP12: =AE12-O12 -> 0.0395 | AQ12: =AF12-O12 -> 0.023833333 | AR12: =AG12-O12 -> -0.027416667 | AS12: =AH12-O12 -> -0.021833333 | AT12: =AI12-O12 -> -0.042083333 | AU12: =AJ12-O12 -> -0.035 | AV12: =AK12-O12 -> -0.0015
A13: 19 | B13: 43581 | C13: 0.42197917 | D13: -20.94 | E13: -20.94 | F13: -20.81 | G13: -20.88 | H13: -21 | I13: -21 | J13: -20.63 | K13: -20.69 | L13: -21.19 | M13: 24.8 | N13: -20.84 | O13: =N13-'Sonde étalon'!$C$12 -> -20.84 | R13: =D13-O13 -> -0.1 | S13: =E13-O13 -> -0.1 | T13: =F13-O13 -> 0.03 | U13: =G13-O13 -> -0.04 | V13: =H13-O13 -> -0.16 | W13: =I13-O13 -> -0.16 | X13: =J13-O13 -> 0.21 | Y13: =K13-O13 -> 0.15 | Z13: =L13-O13 -> -0.35 | AC13: =D13-$R$3 -> -20.862583 | AD13: =E13-$S$3 -> -20.853167 | AE13: =F13-$T$3 -> -20.8305 | AF13: =G13-$U$3 -> -20.856167 | AG13: =H13-$V$3 -> -20.837417 | AH13: =I13-$W$3 -> -20.831833 | AI13: =J13-$X$3 -> -20.852083 | AJ13: =K13-$Y$3 -> -20.845 | AK13: =L13-$Z$3 -> -20.8715 | AN13: =AC13-O13 -> -0.022583333 | AO13: =AD13-O13 -> -0.013166667 | AP13: =AE13-O13 -> 0.0095 | AQ13: =AF13-O13 -> -0.016166667 | AR13: =AG13-O13 -> 0.0025833333 | AS13: =AH13-O13 -> 0.0081666667 | AT13: =AI13-O13 -> -0.012083333 | AU13: =AJ13-O13 -> -0.005 | AV13: =AK13-O13 -> -0.0315
A14: 20 | B14: 43581 | C14: 0.42267361 | D14: -20.94 | E14: -20.94 | F14: -20.81 | G14: -20.88 | H14: -21.06 | I14: -21.06 | J14: -20.63 | K14: -20.69 | L14: -21.19 | M14: 24.8 | N14: -20.88 | O14: =N14-'Sonde étalon'!$C$12 -> -20.88 | R14: =D14-O14 -> -0.06 | S14: =E14-O14 -> -0.06 | T14: =F14-O14 -> 0.07 | U14: =G14-O14 -> 0 | V14: =H14-O14 -> -0.18 | W14: =I14-O14 -> -0.18 | X14: =J14-O14 -> 0.25 | Y14: =K14-O14 -> 0.19 | Z14: =L14-O14 -> -0.31 | AC14: =D14-$R$3 -> -20.862583 | AD14: =E14-$S$3 -> -20.853167 | AE14: =F14-$T$3 -> -20.8305 | AF14: =G14-$U$3 -> -20.856167 | AG14: =H14-$V$3 -> -20.897417 | AH14: =I14-$W$3 -> -20.891833 | AI14: =J14-$X$3 -> -20.852083 | AJ14: =K14-$Y$3 -> -20.845 | AK14: =L14-$Z$3 -> -20.8715 | AN14: =AC14-O14 -> 0.017416667 | AO14: =AD14-O14 -> 0.026833333 | AP14: =AE14-O14 -> 0.0495 | AQ14: =AF14-O14 -> 0.023833333 | AR14: =AG14-O14 -> -0.017416667 | AS14: =AH14-O14 -> -0.011833333 | AT14: =AI14-O14 -> 0.027916667 | AU14: =AJ14-O14 -> 0.035 | AV14: =AK14-O14 -> 0.0085
A15: 21 | B15: 43581 | C15: 0.42336806 | D15: -21 | E15: -21 | F15: -20.88 | G15: -20.94 | H15: -21.06 | I15: -21.06 | J15: -20.69 | K15: -20.75 | L15: -21.19 | M15: 24.8 | N15: -20.9 | O15: =N15-'Sonde étalon'!$C$12 -> -20.9 | R15: =D15-O15 -> -0.1 | S15: =E15-O15 -> -0.1 | T15: =F15-O15 -> 0.02 | U15: =G15-O15 -> -0.04 | V15: =H15-O15 -> -0.16 | W15: =I15-O15 -> -0.16 | X15: =J15-O15 -> 0.21 | Y15: =K15-O15 -> 0.15 | Z15: =L15-O15 -> -0.29 | AC15: =D15-$R$3 -> -20.922583 | AD15: =E15-$S$3 -> -20.913167 | AE15: =F15-$T$3 -> -20.9005 | AF15: =G15-$U$3 -> -20.916167 | AG15: =H15-$V$3 -> -20.897417 | AH15: =I15-$W$3 -> -20.891833 | AI15: =J15-$X$3 -> -20.912083 | AJ15: =K15-$Y$3 -> -20.905 | AK15: =L15-$Z$3 -> -20.8715 | AN15: =AC15-O15 -> -0.022583333 | AO15: =AD15-O15 -> -0.013166667 | AP15: =AE15-O15 -> -0.0005 | AQ15: =AF15-O15 -> -0.016166667 | AR15: =AG15-O15 -> 0.0025833333 | AS15: =AH15-O15 -> 0.0081666667 | AT15: =AI15-O15 -> -0.012083333 | AU15: =AJ15-O15 -> -0.005 | AV15: =AK15-O15 -> 0.0285
A16: 22 | B16: 43581 | C16: 0.4240625 | D16: -21 | E16: -21 | F16: -20.88 | G16: -20.94 | H16: -21.06 | I16: -21.06 | J16: -20.69 | K16: -20.75 | L16: -21.25 | M16: 24.8 | N16: -20.92 | O16: =N16-'Sonde étalon'!$C$12 -> -20.92 | R16: =D16-O16 -> -0.08 | S16: =E16-O16 -> -0.08 | T16: =F16-O16 -> 0.04 | U16: =G16-O16 -> -0.02 | V16: =H16-O16 -> -0.14 | W16: =I16-O16 -> -0.14 | X16: =J16-O16 -> 0.23 | Y16: =K16-O16 -> 0.17 | Z16: =L16-O16 -> -0.33 | AC16: =D16-$R$3 -> -20.922583 | AD16: =E16-$S$3 -> -20.913167 | AE16: =F16-$T$3 -> -20.9005 | AF16: =G16-$U$3 -> -20.916167 | AG16: =H16-$V$3 -> -20.897417 | AH16: =I16-$W$3 -> -20.891833 | AI16: =J16-$X$3 -> -20.912083 | AJ16: =K16-$Y$3 -> -20.905 | AK16: =L16-$Z$3 -> -20.9315 | AN16: =AC16-O16 -> -0.0025833333 | AO16: =AD16-O16 -> 0.0068333333 | AP16: =AE16-O16 -> 0.0195 | AQ16: =AF16-O16 -> 0.0038333333 | AR16: =AG16-O16 -> 0.022583333 | AS16: =AH16-O16 -> 0.028166667 | AT16: =AI16-O16 -> 0.0079166667 | AU16: =AJ16-O16 -> 0.015 | AV16: =AK16-O16 -> -0.0115
A17: 23 | B17: 43581 | C17: 0.42475694 | D17: -21 | E17: -21 | F17: -20.94 | G17: -20.94 | H17: -21.13 | I17: -21.13 | J17: -20.69 | K17: -20.81 | L17: -21.25 | M17: 24.8 | N17: -20.94 | O17: =N17-'Sonde étalon'!$C$12 -> -20.94 | R17: =D17-O17 -> -0.06 | S17: =E17-O17 -> -0.06 | T17: =F17-O17 -> 0 | U17: =G17-O17 -> 0 | V17: =H17-O17 -> -0.19 | W17: =I17-O17 -> -0.19 | X17: =J17-O17 -> 0.25 | Y17: =K17-O17 -> 0.13 | Z17: =L17-O17 -> -0.31 | AC17: =D17-$R$3 -> -20.922583 | AD17: =E17-$S$3 -> -20.913167 | AE17: =F17-$T$3 -> -20.9605 | AF17: =G17-$U$3 -> -20.916167 | AG17: =H17-$V$3 -> -20.967417 | AH17: =I17-$W$3 -> -20.961833 | AI17: =J17-$X$3 -> -20.912083 | AJ17: =K17-$Y$3 -> -20.965 | AK17: =L17-$Z$3 -> -20.9315 | AN17: =AC17-O17 -> 0.017416667 | AO17: =AD17-O17 -> 0.026833333 | AP17: =AE17-O17 -> -0.0205 | AQ17: =AF17-O17 -> 0.023833333 | AR17: =AG17-O17 -> -0.027416667 | AS17: =AH17-O17 -> -0.021833333 | AT17: =AI17-O17 -> 0.027916667 | AU17: =AJ17-O17 -> -0.025 | AV17: =AK17-O17 -> 0.0085
... A125: 131 | B125: 43581 | C125: 0.49975694 | D125: -21.63 | E125: -21.63 | F125: -21.56 | G125: -21.56 | H125: -21.75 | I125: -21.75 | J125: -21.31 | K125: -21.44 | L125: -21.88 | M125: 25 | N125: -21.56 | O125: =N125-'Sonde étalon'!$C$12 -> -21.56 | R125: =D125-O125 -> -0.07 | S125: =E125-O125 -> -0.07 | T125: =F125-O125 -> 0 | U125: =G125-O125 -> 0 | V125: =H125-O125 -> -0.19 | W125: =I125-O125 -> -0.19 | X125: =J125-O125 -> 0.25 | Y125: =K125-O125 -> 0.12 | Z125: =L125-O125 -> -0.32 | AC125: =D125-$R$3 -> -21.552583 | AD125: =E125-$S$3 -> -21.543167 | AE125: =F125-$T$3 -> -21.5805 | AF125: =G125-$U$3 -> -21.536167 | AG125: =H125-$V$3 -> -21.587417 | AH125: =I125-$W$3 -> -21.581833 | AI125: =J125-$X$3 -> -21.532083 | AJ125: =K125-$Y$3 -> -21.595 | AK125: =L125-$Z$3 -> -21.5615 | AN125: =AC125-O125 -> 0.0074166667 | AO125: =AD125-O125 -> 0.016833333 | AP125: =AE125-O125 -> -0.0205 | AQ125: =AF125-O125 -> 0.023833333 | AR125: =AG125-O125 -> -0.027416667 | AS125: =AH125-O125 -> -0.021833333 | AT125: =AI125-O125 -> 0.027916667 | AU125: =AJ125-O125 -> -0.035 | AV125: =AK125-O125 -> -0.0015

Sheet Relevés 5°C
B1: RELEVES | N1: REFERENCE | R1: ERREURS DE JUSTESSE | AC1: RELEVES CORRIGES | AN1: ECARTS
AB2: NB | AC2: =COUNTA(AC6:AC4995) -> 200 | AD2: =COUNTA(AD6:AD4995) -> 200 | AE2: =COUNTA(AE6:AE4995) -> 200 | AF2: =COUNTA(AF6:AF4995) -> 200 | AG2: =COUNTA(AG6:AG4995) -> 200 | AH2: =COUNTA(AH6:AH4995) -> 200 | AI2: =COUNTA(AI6:AI4995) -> 200 | AJ2: =COUNTA(AJ6:AJ4995) -> 200 | AK2: =COUNTA(AK6:AK4995) -> 200 | AM2: NB | AN2: =COUNTA(AN6:AN4995) -> 200 | AO2: =COUNTA(AO6:AO4995) -> 200 | AP2: =COUNTA(AP6:AP4995) -> 200 | AQ2: =COUNTA(AQ6:AQ4995) -> 200 | AR2: =COUNTA(AR6:AR4995) -> 200 | AS2: =COUNTA(AS6:AS4995) -> 200 | AT2: =COUNTA(AT6:AT4995) -> 200 | AU2: =COUNTA(AU6:AU4995) -> 200 | AV2: =COUNTA(AV6:AV4995) -> 200
Q3: Erreur Justesse | R3: =AVERAGE(R6:R4995) -> -0.1091 | S3: =AVERAGE(S6:S4995) -> -0.23705 | T3: =AVERAGE(T6:T4995) -> -0.0899 | U3: =AVERAGE(U6:U4995) -> -0.3436 | V3: =AVERAGE(V6:V4995) -> -0.386 | W3: =AVERAGE(W6:W4995) -> -0.362 | X3: =AVERAGE(X6:X4995) -> 0.03555 | Y3: =AVERAGE(Y6:Y4995) -> -0.0948 | Z3: =AVERAGE(Z6:Z4995) -> -0.63515 | AB3: Ecart type | AC3: =STDEV(AC6:AC4995) -> 1.5308182 | AD3: =STDEV(AD6:AD4995) -> 1.5003388 | AE3: =STDEV(AE6:AE4995) -> 1.5398624 | AF3: =STDEV(AF6:AF4995) -> 1.629898 | AG3: =STDEV(AG6:AG4995) -> 1.5608984 | AH3: =STDEV(AH6:AH4995) -> 1.702085 | AI3: =STDEV(AI6:AI4995) -> 1.4780726 | AJ3: =STDEV(AJ6:AJ4995) -> 1.550647 | AK3: =STDEV(AK6:AK4995) -> 1.6596561 | AM3: Ecart type | AN3: =STDEV(AN6:AN4995) -> 0.089488721 | AO3: =STDEV(AO6:AO4995) -> 0.11352638 | AP3: =STDEV(AP6:AP4995) -> 0.08909365 | AQ3: =STDEV(AQ6:AQ4995) -> 0.15905197 | AR3: =STDEV(AR6:AR4995) -> 0.057028601 | AS3: =STDEV(AS6:AS4995) -> 0.30645977 | AT3: =STDEV(AT6:AT4995) -> 0.13189267 | AU3: =STDEV(AU6:AU4995) -> 0.10458802 | AV3: =STDEV(AV6:AV4995) -> 0.21227407
R4: =STDEV(R6:R4995) -> 0.089488721 | S4: =STDEV(S6:S4995) -> 0.11352638 | T4: =STDEV(T6:T4995) -> 0.08909365 | U4: =STDEV(U6:U4995) -> 0.15905197 | V4: =STDEV(V6:V4995) -> 0.057028601 | W4: =STDEV(W6:W4995) -> 0.30645977 | X4: =STDEV(X6:X4995) -> 0.13189267 | Y4: =STDEV(Y6:Y4995) -> 0.10458802 | Z4: =STDEV(Z6:Z4995) -> 0.21227407 | AB4: Incertitude | AC4: =SQRT((AC3/SQRT(AC2))^2+(('Sonde étalon'!$D$13)/2)^2+(0.0625/(2*SQRT(3)))^2+(0.001/(2*SQRT(3)))^2) -> 0.11680165 | AD4: =SQRT((AD3/SQRT(AD2))^2+(('Sonde étalon'!$D$13)/2)^2+(0.0625/(2*SQRT(3)))^2+(0.001/(2*SQRT(3)))^2) -> 0.11480717 | AE4: =SQRT((AE3/SQRT(AE2))^2+(('Sonde étalon'!$D$13)/2)^2+(0.0625/(2*SQRT(3)))^2+(0.001/(2*SQRT(3)))^2) -> 0.11739457 | AF4: =SQRT((AF3/SQRT(AF2))^2+(('Sonde étalon'!$D$13)/2)^2+(0.0625/(2*SQRT(3)))^2+(0.001/(2*SQRT(3)))^2) -> 0.12332251 | AG4: =SQRT((AG3/SQRT(AG2))^2+(('Sonde étalon'!$D$13)/2)^2+(0.0625/(2*SQRT(3)))^2+(0.001/(2*SQRT(3)))^2) -> 0.11877552 | AH4: =SQRT((AH3/SQRT(AH2))^2+(('Sonde étalon'!$D$13)/2)^2+(0.0625/(2*SQRT(3)))^2+(0.001/(2*SQRT(3)))^2) -> 0.1281057 | AI4: =SQRT((AI3/SQRT(AI2))^2+(('Sonde étalon'!$D$13)/2)^2+(0.0625/(2*SQRT(3)))^2+(0.001/(2*SQRT(3)))^2) -> 0.11335386 | AJ4: =SQRT((AJ3/SQRT(AJ2))^2+(('Sonde étalon'!$D$13)/2)^2+(0.0625/(2*SQRT(3)))^2+(0.001/(2*SQRT(3)))^2) -> 0.11810222 | AK4: =SQRT((AK3/SQRT(AK2))^2+(('Sonde étalon'!$D$13)/2)^2+(0.0625/(2*SQRT(3)))^2+(0.001/(2*SQRT(3)))^2) -> 0.12529124 | AM4: Incertitude | AN4: =SQRT((AN3/SQRT(AN2))^2+(('Sonde étalon'!$D$13)/2)^2+(0.0625/(2*SQRT(3)))^2+(0.01/(2*SQRT(3)))^2) -> 0.044428542 | AO4: =SQRT((AO3/SQRT(AO2))^2+(('Sonde étalon'!$D$13)/2)^2+(0.0625/(2*SQRT(3)))^2+(0.01/(2*SQRT(3)))^2) -> 0.044702297 | AP4: =SQRT((AP3/SQRT(AP2))^2+(('Sonde étalon'!$D$13)/2)^2+(0.0625/(2*SQRT(3)))^2+(0.01/(2*SQRT(3)))^2) -> 0.044424572 | AQ4: =SQRT((AQ3/SQRT(AQ2))^2+(('Sonde étalon'!$D$13)/2)^2+(0.0625/(2*SQRT(3)))^2+(0.01/(2*SQRT(3)))^2) -> 0.045390988 | AR4: =SQRT((AR3/SQRT(AR2))^2+(('Sonde étalon'!$D$13)/2)^2+(0.0625/(2*SQRT(3)))^2+(0.01/(2*SQRT(3)))^2) -> 0.044160112 | AS4: =SQRT((AS3/SQRT(AS2))^2+(('Sonde étalon'!$D$13)/2)^2+(0.0625/(2*SQRT(3)))^2+(0.01/(2*SQRT(3)))^2) -> 0.049024913 | AT4: =SQRT((AT3/SQRT(AT2))^2+(('Sonde étalon'!$D$13)/2)^2+(0.0625/(2*SQRT(3)))^2+(0.01/(2*SQRT(3)))^2) -> 0.044953671 | AU4: =SQRT((AU3/SQRT(AU2))^2+(('Sonde étalon'!$D$13)/2)^2+(0.0625/(2*SQRT(3)))^2+(0.01/(2*SQRT(3)))^2) -> 0.044593132 | AV4: =SQRT((AV3/SQRT(AV2))^2+(('Sonde étalon'!$D$13)/2)^2+(0.0625/(2*SQRT(3)))^2+(0.01/(2*SQRT(3)))^2) -> 0.046466715
A5: Counter | B5: Date | C5: Time | D5: MIL | E5: HGAV | F5: HGAR | G5: HDAV | H5: HDAR | I5: BGAV | J5: BGAR | K5: BDAV | L5: BDAR | N5: Ref | O5: Ref corrigée | R5: MIL | S5: HGAV | T5: HGAR | U5: HDAV | V5: HDAR | W5: BGAV | X5: BGAR | Y5: BDAV | Z5: BDAR | AC5: MIL | AD5: HGAV | AE5: HGAR | AF5: HDAV | AG5: HDAR | AH5: BGAV | AI5: BGAR | AJ5: BDAV | AK5: BDAR | AN5: MIL | AO5: HGAV | AP5: HGAR | AQ5: HDAV | AR5: HDAR | AS5: BGAV | AT5: BGAR | AU5: BDAV | AV5: BDAR
A6: 6 | B6: 43552 | C6: 0.4190162 | D6: 7.19 | E6: 7.06 | F6: 7.25 | G6: 6.94 | H6: 6.94 | I6: 6.69 | J6: 7.25 | K6: 7.19 | L6: 6.5 | N6: 7.22 | O6: =N6-'Sonde étalon'!$C$13 -> 7.39 | R6: =D6-O6 -> -0.2 | S6: =E6-O6 -> -0.33 | T6: =F6-O6 -> -0.14 | U6: =G6-O6 -> -0.45 | V6: =H6-O6 -> -0.45 | W6: =I6-O6 -> -0.7 | X6: =J6-O6 -> -0.14 | Y6: =K6-O6 -> -0.2 | Z6: =L6-O6 -> -0.89 | AC6: =D6-$R$3 -> 7.2991 | AD6: =E6-$S$3 -> 7.29705 | AE6: =F6-$T$3 -> 7.3399 | AF6: =G6-$U$3 -> 7.2836 | AG6: =H6-$V$3 -> 7.326 | AH6: =I6-$W$3 -> 7.052 | AI6: =J6-$X$3 -> 7.21445 | AJ6: =K6-$Y$3 -> 7.2848 | AK6: =L6-$Z$3 -> 7.13515 | AN6: =AC6-O6 -> -0.0909 | AO6: =AD6-O6 -> -0.09295 | AP6: =AE6-O6 -> -0.0501 | AQ6: =AF6-O6 -> -0.1064 | AR6: =AG6-O6 -> -0.064 | AS6: =AH6-O6 -> -0.338 | AT6: =AI6-O6 -> -0.17555 | AU6: =AJ6-O6 -> -0.1052 | AV6: =AK6-O6 -> -0.25485
A7: 7 | B7: 43552 | C7: 0.41971065 | D7: 6.94 | E7: 6.88 | F7: 7 | G7: 6.69 | H7: 6.75 | I7: 6.5 | J7: 7.06 | K7: 7 | L7: 6.31 | N7: 6.96 | O7: =N7-'Sonde étalon'!$C$13 -> 7.13 | R7: =D7-O7 -> -0.19 | S7: =E7-O7 -> -0.25 | T7: =F7-O7 -> -0.13 | U7: =G7-O7 -> -0.44 | V7: =H7-O7 -> -0.38 | W7: =I7-O7 -> -0.63 | X7: =J7-O7 -> -0.07 | Y7: =K7-O7 -> -0.13 | Z7: =L7-O7 -> -0.82 | AC7: =D7-$R$3 -> 7.0491 | AD7: =E7-$S$3 -> 7.11705 | AE7: =F7-$T$3 -> 7.0899 | AF7: =G7-$U$3 -> 7.0336 | AG7: =H7-$V$3 -> 7.136 | AH7: =I7-$W$3 -> 6.862 | AI7: =J7-$X$3 -> 7.02445 | AJ7: =K7-$Y$3 -> 7.0948 | AK7: =L7-$Z$3 -> 6.94515 | AN7: =AC7-O7 -> -0.0809 | AO7: =AD7-O7 -> -0.01295 | AP7: =AE7-O7 -> -0.0401 | AQ7: =AF7-O7 -> -0.0964 | AR7: =AG7-O7 -> 0.006 | AS7: =AH7-O7 -> -0.268 | AT7: =AI7-O7 -> -0.10555 | AU7: =AJ7-O7 -> -0.0352 | AV7: =AK7-O7 -> -0.18485
A8: 8 | B8: 43552 | C8: 0.42040509 | D8: 6.81 | E8: 6.69 | F8: 6.81 | G8: 6.56 | H8: 6.56 | I8: 6.38 | J8: 6.94 | K8: 6.81 | L8: 6.19 | N8: 6.78 | O8: =N8-'Sonde étalon'!$C$13 -> 6.95 | R8: =D8-O8 -> -0.14 | S8: =E8-O8 -> -0.26 | T8: =F8-O8 -> -0.14 | U8: =G8-O8 -> -0.39 | V8: =H8-O8 -> -0.39 | W8: =I8-O8 -> -0.57 | X8: =J8-O8 -> -0.01 | Y8: =K8-O8 -> -0.14 | Z8: =L8-O8 -> -0.76 | AC8: =D8-$R$3 -> 6.9191 | AD8: =E8-$S$3 -> 6.92705 | AE8: =F8-$T$3 -> 6.8999 | AF8: =G8-$U$3 -> 6.9036 | AG8: =H8-$V$3 -> 6.946 | AH8: =I8-$W$3 -> 6.742 | AI8: =J8-$X$3 -> 6.90445 | AJ8: =K8-$Y$3 -> 6.9048 | AK8: =L8-$Z$3 -> 6.82515 | AN8: =AC8-O8 -> -0.0309 | AO8: =AD8-O8 -> -0.02295 | AP8: =AE8-O8 -> -0.0501 | AQ8: =AF8-O8 -> -0.0464 | AR8: =AG8-O8 -> -0.004 | AS8: =AH8-O8 -> -0.208 | AT8: =AI8-O8 -> -0.04555 | AU8: =AJ8-O8 -> -0.0452 | AV8: =AK8-O8 -> -0.12485
A9: 9 | B9: 43552 | C9: 0.42109954 | D9: 6.69 | E9: 6.56 | F9: 6.75 | G9: 6.44 | H9: 6.44 | I9: 6.31 | J9: 6.81 | K9: 6.69 | L9: 6.13 | N9: 6.64 | O9: =N9-'Sonde étalon'!$C$13 -> 6.81 | R9: =D9-O9 -> -0.12 | S9: =E9-O9 -> -0.25 | T9: =F9-O9 -> -0.06 | U9: =G9-O9 -> -0.37 | V9: =H9-O9 -> -0.37 | W9: =I9-O9 -> -0.5 | X9: =J9-O9 -> 0 | Y9: =K9-O9 -> -0.12 | Z9: =L9-O9 -> -0.68 | AC9: =D9-$R$3 -> 6.7991 | AD9: =E9-$S$3 -> 6.79705 | AE9: =F9-$T$3 -> 6.8399 | AF9: =G9-$U$3 -> 6.7836 | AG9: =H9-$V$3 -> 6.826 | AH9: =I9-$W$3 -> 6.672 | AI9: =J9-$X$3 -> 6.77445 | AJ9: =K9-$Y$3 -> 6.7848 | AK9: =L9-$Z$3 -> 6.76515 | AN9: =AC9-O9 -> -0.0109 | AO9: =AD9-O9 -> -0.01295 | AP9: =AE9-O9 -> 0.0299 | AQ9: =AF9-O9 -> -0.0264 | AR9: =AG9-O9 -> 0.016 | AS9: =AH9-O9 -> -0.138 | AT9: =AI9-O9 -> -0.03555 | AU9: =AJ9-O9 -> -0.0252 | AV9: =AK9-O9 -> -0.04485
A10: 10 | B10: 43552 | C10: 0.42179398 | D10: 6.63 | E10: 6.5 | F10: 6.63 | G10: 6.38 | H10: 6.38 | I10: 6.25 | J10: 6.75 | K10: 6.63 | L10: 6.06 | N10: 6.55 | O10: =N10-'Sonde étalon'!$C$13 -> 6.72 | R10: =D10-O10 -> -0.09 | S10: =E10-O10 -> -0.22 | T10: =F10-O10 -> -0.09 | U10: =G10-O10 -> -0.34 | V10: =H10-O10 -> -0.34 | W10: =I10-O10 -> -0.47 | X10: =J10-O10 -> 0.03 | Y10: =K10-O10 -> -0.09 | Z10: =L10-O10 -> -0.66 | AC10: =D10-$R$3 -> 6.7391 | AD10: =E10-$S$3 -> 6.73705 | AE10: =F10-$T$3 -> 6.7199 | AF10: =G10-$U$3 -> 6.7236 | AG10: =H10-$V$3 -> 6.766 | AH10: =I10-$W$3 -> 6.612 | AI10: =J10-$X$3 -> 6.71445 | AJ10: =K10-$Y$3 -> 6.7248 | AK10: =L10-$Z$3 -> 6.69515 | AN10: =AC10-O10 -> 0.0191 | AO10: =AD10-O10 -> 0.01705 | AP10: =AE10-O10 -> -0.0001 | AQ10: =AF10-O10 -> 0.0036 | AR10: =AG10-O10 -> 0.046 | AS10: =AH10-O10 -> -0.108 | AT10: =AI10-O10 -> -0.00555 | AU10: =AJ10-O10 -> 0.0048 | AV10: =AK10-O10 -> -0.02485
A11: 11 | B11: 43552 | C11: 0.42248843 | D11: 6.56 | E11: 6.44 | F11: 6.56 | G11: 6.31 | H11: 6.31 | I11: 6.25 | J11: 6.75 | K11: 6.56 | L11: 6 | N11: 6.54 | O11: =N11-'Sonde étalon'!$C$13 -> 6.71 | R11: =D11-O11 -> -0.15 | S11: =E11-O11 -> -0.27 | T11: =F11-O11 -> -0.15 | U11: =G11-O11 -> -0.4 | V11: =H11-O11 -> -0.4 | W11: =I11-O11 -> -0.46 | X11: =J11-O11 -> 0.04 | Y11: =K11-O11 -> -0.15 | Z11: =L11-O11 -> -0.71 | AC11: =D11-$R$3 -> 6.6691 | AD11: =E11-$S$3 -> 6.67705 | AE11: =F11-$T$3 -> 6.6499 | AF11: =G11-$U$3 -> 6.6536 | AG11: =H11-$V$3 -> 6.696 | AH11: =I11-$W$3 -> 6.612 | AI11: =J11-$X$3 -> 6.71445 | AJ11: =K11-$Y$3 -> 6.6548 | AK11: =L11-$Z$3 -> 6.63515 | AN11: =AC11-O11 -> -0.0409 | AO11: =AD11-O11 -> -0.03295 | AP11: =AE11-O11 -> -0.0601 | AQ11: =AF11-O11 -> -0.0564 | AR11: =AG11-O11 -> -0.014 | AS11: =AH11-O11 -> -0.098 | AT11: =AI11-O11 -> 0.00445 | AU11: =AJ11-O11 -> -0.0552 | AV11: =AK11-O11 -> -0.07485
A12: 12 | B12: 43552 | C12: 0.42318287 | D12: 6.56 | E12: 6.44 | F12: 6.56 | G12: 6.31 | H12: 6.25 | I12: 6.25 | J12: 6.69 | K12: 6.56 | L12: 6 | N12: 6.48 | O12: =N12-'Sonde étalon'!$C$13 -> 6.65 | R12: =D12-O12 -> -0.09 | S12: =E12-O12 -> -0.21 | T12: =F12-O12 -> -0.09 | U12: =G12-O12 -> -0.34 | V12: =H12-O12 -> -0.4 | W12: =I12-O12 -> -0.4 | X12: =J12-O12 -> 0.04 | Y12: =K12-O12 -> -0.09 | Z12: =L12-O12 -> -0.65 | AC12: =D12-$R$3 -> 6.6691 | AD12: =E12-$S$3 -> 6.67705 | AE12: =F12-$T$3 -> 6.6499 | AF12: =G12-$U$3 -> 6.6536 | AG12: =H12-$V$3 -> 6.636 | AH12: =I12-$W$3 -> 6.612 | AI12: =J12-$X$3 -> 6.65445 | AJ12: =K12-$Y$3 -> 6.6548 | AK12: =L12-$Z$3 -> 6.63515 | AN12: =AC12-O12 -> 0.0191 | AO12: =AD12-O12 -> 0.02705 | AP12: =AE12-O12 -> -0.0001 | AQ12: =AF12-O12 -> 0.0036 | AR12: =AG12-O12 -> -0.014 | AS12: =AH12-O12 -> -0.038 | AT12: =AI12-O12 -> 0.00445 | AU12: =AJ12-O12 -> 0.0048 | AV12: =AK12-O12 -> -0.01485
A13: 13 | B13: 43552 | C13: 0.42387731 | D13: 6.56 | E13: 6.44 | F13: 6.56 | G13: 6.31 | H13: 6.25 | I13: 6.25 | J13: 6.69 | K13: 6.56 | L13: 6 | N13: 6.46 | O13: =N13-'Sonde étalon'!$C$13 -> 6.63 | R13: =D13-O13 -> -0.07 | S13: =E13-O13 -> -0.19 | T13: =F13-O13 -> -0.07 | U13: =G13-O13 -> -0.32 | V13: =H13-O13 -> -0.38 | W13: =I13-O13 -> -0.38 | X13: =J13-O13 -> 0.06 | Y13: =K13-O13 -> -0.07 | Z13: =L13-O13 -> -0.63 | AC13: =D13-$R$3 -> 6.6691 | AD13: =E13-$S$3 -> 6.67705 | AE13: =F13-$T$3 -> 6.6499 | AF13: =G13-$U$3 -> 6.6536 | AG13: =H13-$V$3 -> 6.636 | AH13: =I13-$W$3 -> 6.612 | AI13: =J13-$X$3 -> 6.65445 | AJ13: =K13-$Y$3 -> 6.6548 | AK13: =L13-$Z$3 -> 6.63515 | AN13: =AC13-O13 -> 0.0391 | AO13: =AD13-O13 -> 0.04705 | AP13: =AE13-O13 -> 0.0199 | AQ13: =AF13-O13 -> 0.0236 | AR13: =AG13-O13 -> 0.006 | AS13: =AH13-O13 -> -0.018 | AT13: =AI13-O13 -> 0.02445 | AU13: =AJ13-O13 -> 0.0248 | AV13: =AK13-O13 -> 0.00515
A14: 14 | B14: 43552 | C14: 0.42457176 | D14: 6.56 | E14: 6.44 | F14: 6.56 | G14: 6.31 | H14: 6.25 | I14: 6.25 | J14: 6.69 | K14: 6.56 | L14: 6 | N14: 6.45 | O14: =N14-'Sonde étalon'!$C$13 -> 6.62 | R14: =D14-O14 -> -0.06 | S14: =E14-O14 -> -0.18 | T14: =F14-O14 -> -0.06 | U14: =G14-O14 -> -0.31 | V14: =H14-O14 -> -0.37 | W14: =I14-O14 -> -0.37 | X14: =J14-O14 -> 0.07 | Y14: =K14-O14 -> -0.06 | Z14: =L14-O14 -> -0.62 | AC14: =D14-$R$3 -> 6.6691 | AD14: =E14-$S$3 -> 6.67705 | AE14: =F14-$T$3 -> 6.6499 | AF14: =G14-$U$3 -> 6.6536 | AG14: =H14-$V$3 -> 6.636 | AH14: =I14-$W$3 -> 6.612 | AI14: =J14-$X$3 -> 6.65445 | AJ14: =K14-$Y$3 -> 6.6548 | AK14: =L14-$Z$3 -> 6.63515 | AN14: =AC14-O14 -> 0.0491 | AO14: =AD14-O14 -> 0.05705 | AP14: =AE14-O14 -> 0.0299 | AQ14: =AF14-O14 -> 0.0336 | AR14: =AG14-O14 -> 0.016 | AS14: =AH14-O14 -> -0.008 | AT14: =AI14-O14 -> 0.03445 | AU14: =AJ14-O14 -> 0.0348 | AV14: =AK14-O14 -> 0.01515
A15: 15 | B15: 43552 | C15: 0.4252662 | D15: 6.56 | E15: 6.44 | F15: 6.56 | G15: 6.31 | H15: 6.25 | I15: 6.31 | J15: 6.69 | K15: 6.56 | L15: 6 | N15: 6.46 | O15: =N15-'Sonde étalon'!$C$13 -> 6.63 | R15: =D15-O15 -> -0.07 | S15: =E15-O15 -> -0.19 | T15: =F15-O15 -> -0.07 | U15: =G15-O15 -> -0.32 | V15: =H15-O15 -> -0.38 | W15: =I15-O15 -> -0.32 | X15: =J15-O15 -> 0.06 | Y15: =K15-O15 -> -0.07 | Z15: =L15-O15 -> -0.63 | AC15: =D15-$R$3 -> 6.6691 | AD15: =E15-$S$3 -> 6.67705 | AE15: =F15-$T$3 -> 6.6499 | AF15: =G15-$U$3 -> 6.6536 | AG15: =H15-$V$3 -> 6.636 | AH15: =I15-$W$3 -> 6.672 | AI15: =J15-$X$3 -> 6.65445 | AJ15: =K15-$Y$3 -> 6.6548 | AK15: =L15-$Z$3 -> 6.63515 | AN15: =AC15-O15 -> 0.0391 | AO15: =AD15-O15 -> 0.04705 | AP15: =AE15-O15 -> 0.0199 | AQ15: =AF15-O15 -> 0.0236 | AR15: =AG15-O15 -> 0.006 | AS15: =AH15-O15 -> 0.042 | AT15: =AI15-O15 -> 0.02445 | AU15: =AJ15-O15 -> 0.0248 | AV15: =AK15-O15 -> 0.00515
A16: 16 | B16: 43552 | C16: 0.42596065 | D16: 6.56 | E16: 6.44 | F16: 6.56 | G16: 6.31 | H16: 6.31 | I16: 6.31 | J16: 6.75 | K16: 6.56 | L16: 6.06 | N16: 6.46 | O16: =N16-'Sonde étalon'!$C$13 -> 6.63 | R16: =D16-O16 -> -0.07 | S16: =E16-O16 -> -0.19 | T16: =F16-O16 -> -0.07 | U16: =G16-O16 -> -0.32 | V16: =H16-O16 -> -0.32 | W16: =I16-O16 -> -0.32 | X16: =J16-O16 -> 0.12 | Y16: =K16-O16 -> -0.07 | Z16: =L16-O16 -> -0.57 | AC16: =D16-$R$3 -> 6.6691 | AD16: =E16-$S$3 -> 6.67705 | AE16: =F16-$T$3 -> 6.6499 | AF16: =G16-$U$3 -> 6.6536 | AG16: =H16-$V$3 -> 6.696 | AH16: =I16-$W$3 -> 6.672 | AI16: =J16-$X$3 -> 6.71445 | AJ16: =K16-$Y$3 -> 6.6548 | AK16: =L16-$Z$3 -> 6.69515 | AN16: =AC16-O16 -> 0.0391 | AO16: =AD16-O16 -> 0.04705 | AP16: =AE16-O16 -> 0.0199 | AQ16: =AF16-O16 -> 0.0236 | AR16: =AG16-O16 -> 0.066 | AS16: =AH16-O16 -> 0.042 | AT16: =AI16-O16 -> 0.08445 | AU16: =AJ16-O16 -> 0.0248 | AV16: =AK16-O16 -> 0.06515
A17: 17 | B17: 43552 | C17: 0.42665509 | D17: 6.63 | E17: 6.44 | F17: 6.63 | G17: 6.38 | H17: 6.31 | I17: 6.31 | J17: 6.75 | K17: 6.63 | L17: 6.06 | N17: 6.48 | O17: =N17-'Sonde étalon'!$C$13 -> 6.65 | R17: =D17-O17 -> -0.02 | S17: =E17-O17 -> -0.21 | T17: =F17-O17 -> -0.02 | U17: =G17-O17 -> -0.27 | V17: =H17-O17 -> -0.34 | W17: =I17-O17 -> -0.34 | X17: =J17-O17 -> 0.1 | Y17: =K17-O17 -> -0.02 | Z17: =L17-O17 -> -0.59 | AC17: =D17-$R$3 -> 6.7391 | AD17: =E17-$S$3 -> 6.67705 | AE17: =F17-$T$3 -> 6.7199 | AF17: =G17-$U$3 -> 6.7236 | AG17: =H17-$V$3 -> 6.696 | AH17: =I17-$W$3 -> 6.672 | AI17: =J17-$X$3 -> 6.71445 | AJ17: =K17-$Y$3 -> 6.7248 | AK17: =L17-$Z$3 -> 6.69515 | AN17: =AC17-O17 -> 0.0891 | AO17: =AD17-O17 -> 0.02705 | AP17: =AE17-O17 -> 0.0699 | AQ17: =AF17-O17 -> 0.0736 | AR17: =AG17-O17 -> 0.046 | AS17: =AH17-O17 -> 0.022 | AT17: =AI17-O17 -> 0.06445 | AU17: =AJ17-O17 -> 0.0748 | AV17: =AK17-O17 -> 0.04515
... A205: 205 | B205: 43552 | C205: 0.55721065 | D205: 8.94 | E205: 8.75 | F205: 8.94 | G205: 8.81 | H205: 8.63 | I205: 8.88 | J205: 9 | K205: 8.94 | L205: 8.56 | N205: 8.88 | O205: =N205-'Sonde étalon'!$C$13 -> 9.05 | R205: =D205-O205 -> -0.11 | S205: =E205-O205 -> -0.3 | T205: =F205-O205 -> -0.11 | U205: =G205-O205 -> -0.24 | V205: =H205-O205 -> -0.42 | W205: =I205-O205 -> -0.17 | X205: =J205-O205 -> -0.05 | Y205: =K205-O205 -> -0.11 | Z205: =L205-O205 -> -0.49 | AC205: =D205-$R$3 -> 9.0491 | AD205: =E205-$S$3 -> 8.98705 | AE205: =F205-$T$3 -> 9.0299 | AF205: =G205-$U$3 -> 9.1536 | AG205: =H205-$V$3 -> 9.016 | AH205: =I205-$W$3 -> 9.242 | AI205: =J205-$X$3 -> 8.96445 | AJ205: =K205-$Y$3 -> 9.0348 | AK205: =L205-$Z$3 -> 9.19515 | AN205: =AC205-O205 -> -0.0009 | AO205: =AD205-O205 -> -0.06295 | AP205: =AE205-O205 -> -0.0201 | AQ205: =AF205-O205 -> 0.1036 | AR205: =AG205-O205 -> -0.034 | AS205: =AH205-O205 -> 0.192 | AT205: =AI205-O205 -> -0.08555 | AU205: =AJ205-O205 -> -0.0152 | AV205: =AK205-O205 -> 0.14515

Sheet Relevés 20°C
B1: RELEVES | P1: REFERENCE | T1: ERREURS DE JUSTESSE | AF1: RELEVES CORRIGES | AR1: ECARTS
AE2: NB | AF2: =COUNTA(AF6:AF4997) -> 71 | AG2: =COUNTA(AG6:AG4997) -> 71 | AH2: =COUNTA(AH6:AH4997) -> 71 | AI2: =COUNTA(AI6:AI4997) -> 71 | AJ2: =COUNTA(AJ6:AJ4997) -> 71 | AK2: =COUNTA(AK6:AK4997) -> 71 | AL2: =COUNTA(AL6:AL4997) -> 71 | AM2: =COUNTA(AM6:AM4997) -> 71 | ... AO2: =COUNTA(AO6:AO4997) -> 71 | AQ2: NB | AR2: =COUNTA(AR6:AR4995) -> 71 | AS2: =COUNTA(AS6:AS4995) -> 71 | AT2: =COUNTA(AT6:AT4995) -> 71 | AU2: =COUNTA(AU6:AU4995) -> 71 | AV2: =COUNTA(AV6:AV4995) -> 71 | AW2: =COUNTA(AW6:AW4995) -> 71 | AX2: =COUNTA(AX6:AX4995) -> 71 | AY2: =COUNTA(AY6:AY4995) -> 71 | AZ2: =COUNTA(AZ6:AZ4995) -> 71 | BA2: =COUNTA(BA6:BA4997) -> 71
S3: Erreur Justesse | T3: =AVERAGE(T6:T4997) -> -0.15183099 | U3: =AVERAGE(U6:U4997) -> -0.22056338 | V3: =AVERAGE(V6:V4997) -> -0.24140845 | W3: =AVERAGE(W6:W4997) -> -0.2156338 | X3: =AVERAGE(X6:X4997) -> -0.23380282 | Y3: =AVERAGE(Y6:Y4997) -> -0.13816901 | Z3: =AVERAGE(Z6:Z4997) -> -0.024788732 | AA3: =AVERAGE(AA6:AA4997) -> -0.090140845 | ... AC3: =AVERAGE(AC6:AC4997) -> 2.608169 | AE3: Ecart type | AF3: =STDEV(AF6:AF4997) -> 0.20323094 | AG3: =STDEV(AG6:AG4997) -> 0.1706746 | AH3: =STDEV(AH6:AH4997) -> 0.19565224 | AI3: =STDEV(AI6:AI4997) -> 0.18187742 | AJ3: =STDEV(AJ6:AJ4997) -> 0.203633 | AK3: =STDEV(AK6:AK4997) -> 0.22160209 | AL3: =STDEV(AL6:AL4997) -> 0.19530073 | AM3: =STDEV(AM6:AM4997) -> 0.20173533 | ... AO3: =STDEV(AO6:AO4997) -> 0.18996982 | AQ3: Ecart type | AR3: =STDEV(AR6:AR4995) -> 0.042200537 | AS3: =STDEV(AS6:AS4995) -> 0.070404694 | AT3: =STDEV(AT6:AT4995) -> 0.03848175 | AU3: =STDEV(AU6:AU4995) -> 0.048158441 | AV3: =STDEV(AV6:AV4995) -> 0.031092773 | AW3: =STDEV(AW6:AW4995) -> 0.039867991 | AX3: =STDEV(AX6:AX4995) -> 0.049334403 | AY3: =STDEV(AY6:AY4995) -> 0.032841305 | AZ3: =STDEV(AZ6:AZ4995) -> 0.036991488 | BA3: =STDEV(BA6:BA4997) -> 0.087901078
AE4: Incertitude | AF4: =SQRT((AF3/SQRT(AF2))^2+(('Sonde étalon'!$D$14)/2)^2+(0.0625/(2*SQRT(3)))^2+(0.001/(2*SQRT(3)))^2) -> 0.050073286 | AG4: =SQRT((AG3/SQRT(AG2))^2+(('Sonde étalon'!$D$14)/2)^2+(0.0625/(2*SQRT(3)))^2+(0.001/(2*SQRT(3)))^2) -> 0.048330977 | AH4: =SQRT((AH3/SQRT(AH2))^2+(('Sonde étalon'!$D$14)/2)^2+(0.0625/(2*SQRT(3)))^2+(0.001/(2*SQRT(3)))^2) -> 0.049646312 | AI4: =SQRT((AI3/SQRT(AI2))^2+(('Sonde étalon'!$D$14)/2)^2+(0.0625/(2*SQRT(3)))^2+(0.001/(2*SQRT(3)))^2) -> 0.048903079 | AJ4: =SQRT((AJ3/SQRT(AJ2))^2+(('Sonde étalon'!$D$14)/2)^2+(0.0625/(2*SQRT(3)))^2+(0.001/(2*SQRT(3)))^2) -> 0.050096287 | AK4: =SQRT((AK3/SQRT(AK2))^2+(('Sonde étalon'!$D$14)/2)^2+(0.0625/(2*SQRT(3)))^2+(0.001/(2*SQRT(3)))^2) -> 0.051159152 | AL4: =SQRT((AL3/SQRT(AL2))^2+(('Sonde étalon'!$D$14)/2)^2+(0.0625/(2*SQRT(3)))^2+(0.001/(2*SQRT(3)))^2) -> 0.049626814 | AM4: =SQRT((AM3/SQRT(AM2))^2+(('Sonde étalon'!$D$14)/2)^2+(0.0625/(2*SQRT(3)))^2+(0.001/(2*SQRT(3)))^2) -> 0.049988032 | AN4: =SQRT((AN3/SQRT(AN2))^2+(('Sonde étalon'!$D$14)/2)^2+(0.0625/(2*SQRT(3)))^2+(0.001/(2*SQRT(3)))^2) -> 0.049864831 | AO4: =SQRT((AO3/SQRT(AO2))^2+(('Sonde étalon'!$D$14)/2)^2+(1/(2*SQRT(3)))^2+(0.001/(2*SQRT(3)))^2) -> 0.29230413 | AQ4: Incertitude | AR4: =SQRT((AR3/SQRT(AR2))^2+(('Sonde étalon'!$D$13)/2)^2+(0.0625/(2*SQRT(3)))^2+(0.01/(2*SQRT(3)))^2) -> 0.044259881 | AS4: =SQRT((AS3/SQRT(AS2))^2+(('Sonde étalon'!$D$13)/2)^2+(0.0625/(2*SQRT(3)))^2+(0.01/(2*SQRT(3)))^2) -> 0.044762356 | AT4: =SQRT((AT3/SQRT(AT2))^2+(('Sonde étalon'!$D$13)/2)^2+(0.0625/(2*SQRT(3)))^2+(0.01/(2*SQRT(3)))^2) -> 0.044212115 | AU4: =SQRT((AU3/SQRT(AU2))^2+(('Sonde étalon'!$D$13)/2)^2+(0.0625/(2*SQRT(3)))^2+(0.01/(2*SQRT(3)))^2) -> 0.044345456 | AV4: =SQRT((AV3/SQRT(AV2))^2+(('Sonde étalon'!$D$13)/2)^2+(0.0625/(2*SQRT(3)))^2+(0.01/(2*SQRT(3)))^2) -> 0.044130154 | AW4: =SQRT((AW3/SQRT(AW2))^2+(('Sonde étalon'!$D$13)/2)^2+(0.0625/(2*SQRT(3)))^2+(0.01/(2*SQRT(3)))^2) -> 0.044229412 | AX4: =SQRT((AX3/SQRT(AX2))^2+(('Sonde étalon'!$D$13)/2)^2+(0.0625/(2*SQRT(3)))^2+(0.01/(2*SQRT(3)))^2) -> 0.044363659 | AY4: =SQRT((AY3/SQRT(AY2))^2+(('Sonde étalon'!$D$13)/2)^2+(0.0625/(2*SQRT(3)))^2+(0.01/(2*SQRT(3)))^2) -> 0.04414799 | AZ4: =SQRT((AZ3/SQRT(AZ2))^2+(('Sonde étalon'!$D$13)/2)^2+(0.0625/(2*SQRT(3)))^2+(0.01/(2*SQRT(3)))^2) -> 0.044194196 | BA4: =SQRT((BA3/SQRT(BA2))^2+(('Sonde étalon'!$D$14)/2)^2+(1/(2*SQRT(3)))^2+(0.01/(2*SQRT(3)))^2) -> 0.29163417
A5: Counter | B5: Date | C5: Time | D5: MIL | E5: HGAV | F5: HGAR | G5: HDAV | H5: HDAR | I5: BGAV | J5: BGAR | K5: BDAV | L5: BDAR | M5: T°AMB | N5: %HR AMB | P5: Ref | Q5: Ref corrigée | T5: MIL | U5: HGAV | V5: HGAR | W5: HDAV | X5: HDAR | Y5: BGAV | Z5: BGAR | AA5: BDAV | AB5: BDAR | AC5: T°AMB | AF5: MIL | AG5: HGAV | AH5: HGAR | AI5: HDAV | AJ5: HDAR | AK5: BGAV | AL5: BGAR | AM5: BDAV | AN5: BDAR | AO5: T°AMB | AR5: MIL | AS5: HGAV | AT5: HGAR | AU5: HDAV | AV5: HDAR | AW5: BGAV | AX5: BGAR | AY5: BDAV | AZ5: BDAR | BA5: T°AMB
A6: 3 | B6: 43551 | C6: 0.66053241 | D6: 24 | E6: 24 | F6: 23.88 | G6: 23.94 | H6: 23.88 | I6: 24 | J6: 24.13 | K6: 24.06 | L6: 23.81 | M6: 26.7 | N6: 19 | P6: 23.93 | Q6: =P6-'Sonde étalon'!$C$14 -> 24.1 | T6: =D6-Q6 -> -0.1 | U6: =E6-Q6 -> -0.1 | V6: =F6-Q6 -> -0.22 | W6: =G6-Q6 -> -0.16 | X6: =H6-Q6 -> -0.22 | Y6: =I6-Q6 -> -0.1 | Z6: =J6-Q6 -> 0.03 | AA6: =K6-Q6 -> -0.04 | AB6: =L6-Q6 -> -0.29 | AC6: =M6-Q6 -> 2.6 | AF6: =D6-$T$3 -> 24.151831 | AG6: =E6-$U$3 -> 24.220563 | AH6: =F6-$V$3 -> 24.121408 | AI6: =G6-$W$3 -> 24.155634 | AJ6: =H6-$X$3 -> 24.113803 | AK6: =I6-$Y$3 -> 24.138169 | AL6: =J6-$Z$3 -> 24.154789 | AM6: =K6-$AA$3 -> 24.150141 | AN6: =L6-$AB$3 -> 24.158732 | AO6: =M6-$AC$3 -> 24.091831 | AR6: =AF6-Q6 -> 0.051830986 | AS6: =AG6-Q6 -> 0.12056338 | AT6: =AH6-Q6 -> 0.021408451 | AU6: =AI6-Q6 -> 0.055633803 | AV6: =AJ6-Q6 -> 0.013802817 | AW6: =AK6-Q6 -> 0.038169014 | AX6: =AL6-Q6 -> 0.054788732 | AY6: =AM6-Q6 -> 0.050140845 | AZ6: =AN6-Q6 -> 0.058732394 | BA6: =AO6-Q6 -> -0.0081690141
A7: 4 | B7: 43551 | C7: 0.66122685 | D7: 24 | E7: 24 | F7: 23.88 | G7: 24 | H7: 23.94 | I7: 24 | J7: 24.19 | K7: 24.06 | L7: 23.81 | M7: 26.7 | N7: 19 | P7: 23.97 | Q7: =P7-'Sonde étalon'!$C$14 -> 24.14 | T7: =D7-Q7 -> -0.14 | U7: =E7-Q7 -> -0.14 | V7: =F7-Q7 -> -0.26 | W7: =G7-Q7 -> -0.14 | X7: =H7-Q7 -> -0.2 | Y7: =I7-Q7 -> -0.14 | Z7: =J7-Q7 -> 0.05 | AA7: =K7-Q7 -> -0.08 | AB7: =L7-Q7 -> -0.33 | AC7: =M7-Q7 -> 2.56 | AF7: =D7-$T$3 -> 24.151831 | AG7: =E7-$U$3 -> 24.220563 | AH7: =F7-$V$3 -> 24.121408 | AI7: =G7-$W$3 -> 24.215634 | AJ7: =H7-$X$3 -> 24.173803 | AK7: =I7-$Y$3 -> 24.138169 | AL7: =J7-$Z$3 -> 24.214789 | AM7: =K7-$AA$3 -> 24.150141 | AN7: =L7-$AB$3 -> 24.158732 | AO7: =M7-$AC$3 -> 24.091831 | AR7: =AF7-Q7 -> 0.011830986 | AS7: =AG7-Q7 -> 0.08056338 | AT7: =AH7-Q7 -> -0.018591549 | AU7: =AI7-Q7 -> 0.075633803 | AV7: =AJ7-Q7 -> 0.033802817 | AW7: =AK7-Q7 -> -0.0018309859 | AX7: =AL7-Q7 -> 0.074788732 | AY7: =AM7-Q7 -> 0.010140845 | AZ7: =AN7-Q7 -> 0.018732394 | BA7: =AO7-Q7 -> -0.048169014
A8: 5 | B8: 43551 | C8: 0.6619213 | D8: 24.06 | E8: 24.06 | F8: 23.94 | G8: 24 | H8: 23.94 | I8: 24 | J8: 24.19 | K8: 24.06 | L8: 23.88 | M8: 26.7 | N8: 19 | P8: 23.94 | Q8: =P8-'Sonde étalon'!$C$14 -> 24.11 | T8: =D8-Q8 -> -0.05 | U8: =E8-Q8 -> -0.05 | V8: =F8-Q8 -> -0.17 | W8: =G8-Q8 -> -0.11 | X8: =H8-Q8 -> -0.17 | Y8: =I8-Q8 -> -0.11 | Z8: =J8-Q8 -> 0.08 | AA8: =K8-Q8 -> -0.05 | AB8: =L8-Q8 -> -0.23 | AC8: =M8-Q8 -> 2.59 | AF8: =D8-$T$3 -> 24.211831 | AG8: =E8-$U$3 -> 24.280563 | AH8: =F8-$V$3 -> 24.181408 | AI8: =G8-$W$3 -> 24.215634 | AJ8: =H8-$X$3 -> 24.173803 | AK8: =I8-$Y$3 -> 24.138169 | AL8: =J8-$Z$3 -> 24.214789 | AM8: =K8-$AA$3 -> 24.150141 | AN8: =L8-$AB$3 -> 24.228732 | AO8: =M8-$AC$3 -> 24.091831 | AR8: =AF8-Q8 -> 0.10183099 | AS8: =AG8-Q8 -> 0.17056338 | AT8: =AH8-Q8 -> 0.071408451 | AU8: =AI8-Q8 -> 0.1056338 | AV8: =AJ8-Q8 -> 0.063802817 | AW8: =AK8-Q8 -> 0.028169014 | AX8: =AL8-Q8 -> 0.10478873 | AY8: =AM8-Q8 -> 0.040140845 | AZ8: =AN8-Q8 -> 0.11873239 | BA8: =AO8-Q8 -> -0.018169014
A9: 6 | B9: 43551 | C9: 0.66261574 | D9: 24.06 | E9: 24.06 | F9: 23.94 | G9: 24 | H9: 23.94 | I9: 24 | J9: 24.19 | K9: 24.13 | L9: 23.81 | M9: 26.8 | N9: 19 | P9: 23.97 | Q9: =P9-'Sonde étalon'!$C$14 -> 24.14 | T9: =D9-Q9 -> -0.08 | U9: =E9-Q9 -> -0.08 | V9: =F9-Q9 -> -0.2 | W9: =G9-Q9 -> -0.14 | X9: =H9-Q9 -> -0.2 | Y9: =I9-Q9 -> -0.14 | Z9: =J9-Q9 -> 0.05 | AA9: =K9-Q9 -> -0.01 | AB9: =L9-Q9 -> -0.33 | AC9: =M9-Q9 -> 2.66 | AF9: =D9-$T$3 -> 24.211831 | AG9: =E9-$U$3 -> 24.280563 | AH9: =F9-$V$3 -> 24.181408 | AI9: =G9-$W$3 -> 24.215634 | AJ9: =H9-$X$3 -> 24.173803 | AK9: =I9-$Y$3 -> 24.138169 | AL9: =J9-$Z$3 -> 24.214789 | AM9: =K9-$AA$3 -> 24.220141 | AN9: =L9-$AB$3 -> 24.158732 | AO9: =M9-$AC$3 -> 24.191831 | AR9: =AF9-Q9 -> 0.071830986 | AS9: =AG9-Q9 -> 0.14056338 | AT9: =AH9-Q9 -> 0.041408451 | AU9: =AI9-Q9 -> 0.075633803 | AV9: =AJ9-Q9 -> 0.033802817 | AW9: =AK9-Q9 -> -0.0018309859 | AX9: =AL9-Q9 -> 0.074788732 | AY9: =AM9-Q9 -> 0.080140845 | AZ9: =AN9-Q9 -> 0.018732394 | BA9: =AO9-Q9 -> 0.051830986
A10: 7 | B10: 43551 | C10: 0.66331019 | D10: 24.06 | E10: 24.06 | F10: 23.94 | G10: 24.06 | H10: 23.94 | I10: 24.06 | J10: 24.25 | K10: 24.13 | L10: 23.88 | M10: 26.8 | N10: 19 | P10: 24.02 | Q10: =P10-'Sonde étalon'!$C$14 -> 24.19 | T10: =D10-Q10 -> -0.13 | U10: =E10-Q10 -> -0.13 | V10: =F10-Q10 -> -0.25 | W10: =G10-Q10 -> -0.13 | X10: =H10-Q10 -> -0.25 | Y10: =I10-Q10 -> -0.13 | Z10: =J10-Q10 -> 0.06 | AA10: =K10-Q10 -> -0.06 | AB10: =L10-Q10 -> -0.31 | AC10: =M10-Q10 -> 2.61 | AF10: =D10-$T$3 -> 24.211831 | AG10: =E10-$U$3 -> 24.280563 | AH10: =F10-$V$3 -> 24.181408 | AI10: =G10-$W$3 -> 24.275634 | AJ10: =H10-$X$3 -> 24.173803 | AK10: =I10-$Y$3 -> 24.198169 | AL10: =J10-$Z$3 -> 24.274789 | AM10: =K10-$AA$3 -> 24.220141 | AN10: =L10-$AB$3 -> 24.228732 | AO10: =M10-$AC$3 -> 24.191831 | AR10: =AF10-Q10 -> 0.021830986 | AS10: =AG10-Q10 -> 0.09056338 | AT10: =AH10-Q10 -> -0.0085915493 | AU10: =AI10-Q10 -> 0.085633803 | AV10: =AJ10-Q10 -> -0.016197183 | AW10: =AK10-Q10 -> 0.0081690141 | AX10: =AL10-Q10 -> 0.084788732 | AY10: =AM10-Q10 -> 0.030140845 | AZ10: =AN10-Q10 -> 0.038732394 | BA10: =AO10-Q10 -> 0.0018309859
A11: 8 | B11: 43551 | C11: 0.66400463 | D11: 24.06 | E11: 24.06 | F11: 23.94 | G11: 24 | H11: 23.94 | I11: 24.06 | J11: 24.25 | K11: 24.13 | L11: 23.88 | M11: 26.8 | N11: 19 | P11: 24 | Q11: =P11-'Sonde étalon'!$C$14 -> 24.17 | T11: =D11-Q11 -> -0.11 | U11: =E11-Q11 -> -0.11 | V11: =F11-Q11 -> -0.23 | W11: =G11-Q11 -> -0.17 | X11: =H11-Q11 -> -0.23 | Y11: =I11-Q11 -> -0.11 | Z11: =J11-Q11 -> 0.08 | AA11: =K11-Q11 -> -0.04 | AB11: =L11-Q11 -> -0.29 | AC11: =M11-Q11 -> 2.63 | AF11: =D11-$T$3 -> 24.211831 | AG11: =E11-$U$3 -> 24.280563 | AH11: =F11-$V$3 -> 24.181408 | AI11: =G11-$W$3 -> 24.215634 | AJ11: =H11-$X$3 -> 24.173803 | AK11: =I11-$Y$3 -> 24.198169 | AL11: =J11-$Z$3 -> 24.274789 | AM11: =K11-$AA$3 -> 24.220141 | AN11: =L11-$AB$3 -> 24.228732 | AO11: =M11-$AC$3 -> 24.191831 | AR11: =AF11-Q11 -> 0.041830986 | AS11: =AG11-Q11 -> 0.11056338 | AT11: =AH11-Q11 -> 0.011408451 | AU11: =AI11-Q11 -> 0.045633803 | AV11: =AJ11-Q11 -> 0.0038028169 | AW11: =AK11-Q11 -> 0.028169014 | AX11: =AL11-Q11 -> 0.10478873 | AY11: =AM11-Q11 -> 0.050140845 | AZ11: =AN11-Q11 -> 0.058732394 | BA11: =AO11-Q11 -> 0.021830986
A12: 9 | B12: 43551 | C12: 0.66469907 | D12: 24.06 | E12: 24.13 | F12: 24 | G12: 24.06 | H12: 24 | I12: 24.06 | J12: 24.25 | K12: 24.13 | L12: 23.88 | M12: 26.8 | N12: 19 | P12: 24.02 | Q12: =P12-'Sonde étalon'!$C$14 -> 24.19 | T12: =D12-Q12 -> -0.13 | U12: =E12-Q12 -> -0.06 | V12: =F12-Q12 -> -0.19 | W12: =G12-Q12 -> -0.13 | X12: =H12-Q12 -> -0.19 | Y12: =I12-Q12 -> -0.13 | Z12: =J12-Q12 -> 0.06 | AA12: =K12-Q12 -> -0.06 | AB12: =L12-Q12 -> -0.31 | AC12: =M12-Q12 -> 2.61 | AF12: =D12-$T$3 -> 24.211831 | AG12: =E12-$U$3 -> 24.350563 | AH12: =F12-$V$3 -> 24.241408 | AI12: =G12-$W$3 -> 24.275634 | AJ12: =H12-$X$3 -> 24.233803 | AK12: =I12-$Y$3 -> 24.198169 | AL12: =J12-$Z$3 -> 24.274789 | AM12: =K12-$AA$3 -> 24.220141 | AN12: =L12-$AB$3 -> 24.228732 | AO12: =M12-$AC$3 -> 24.191831 | AR12: =AF12-Q12 -> 0.021830986 | AS12: =AG12-Q12 -> 0.16056338 | AT12: =AH12-Q12 -> 0.051408451 | AU12: =AI12-Q12 -> 0.085633803 | AV12: =AJ12-Q12 -> 0.043802817 | AW12: =AK12-Q12 -> 0.0081690141 | AX12: =AL12-Q12 -> 0.084788732 | AY12: =AM12-Q12 -> 0.030140845 | AZ12: =AN12-Q12 -> 0.038732394 | BA12: =AO12-Q12 -> 0.0018309859
A13: 10 | B13: 43551 | C13: 0.66539352 | D13: 24.06 | E13: 24.06 | F13: 24 | G13: 24.06 | H13: 24 | I13: 24.06 | J13: 24.25 | K13: 24.13 | L13: 23.88 | M13: 26.8 | N13: 18 | P13: 24.03 | Q13: =P13-'Sonde étalon'!$C$14 -> 24.2 | T13: =D13-Q13 -> -0.14 | U13: =E13-Q13 -> -0.14 | V13: =F13-Q13 -> -0.2 | W13: =G13-Q13 -> -0.14 | X13: =H13-Q13 -> -0.2 | Y13: =I13-Q13 -> -0.14 | Z13: =J13-Q13 -> 0.05 | AA13: =K13-Q13 -> -0.07 | AB13: =L13-Q13 -> -0.32 | AC13: =M13-Q13 -> 2.6 | AF13: =D13-$T$3 -> 24.211831 | AG13: =E13-$U$3 -> 24.280563 | AH13: =F13-$V$3 -> 24.241408 | AI13: =G13-$W$3 -> 24.275634 | AJ13: =H13-$X$3 -> 24.233803 | AK13: =I13-$Y$3 -> 24.198169 | AL13: =J13-$Z$3 -> 24.274789 | AM13: =K13-$AA$3 -> 24.220141 | AN13: =L13-$AB$3 -> 24.228732 | AO13: =M13-$AC$3 -> 24.191831 | AR13: =AF13-Q13 -> 0.011830986 | AS13: =AG13-Q13 -> 0.08056338 | AT13: =AH13-Q13 -> 0.041408451 | AU13: =AI13-Q13 -> 0.075633803 | AV13: =AJ13-Q13 -> 0.033802817 | AW13: =AK13-Q13 -> -0.0018309859 | AX13: =AL13-Q13 -> 0.074788732 | AY13: =AM13-Q13 -> 0.020140845 | AZ13: =AN13-Q13 -> 0.028732394 | BA13: =AO13-Q13 -> -0.0081690141
A14: 11 | B14: 43551 | C14: 0.66608796 | D14: 24.06 | E14: 24.06 | F14: 23.94 | G14: 24.06 | H14: 24 | I14: 24 | J14: 24.25 | K14: 24.13 | L14: 23.88 | M14: 26.8 | N14: 18 | P14: 24.03 | Q14: =P14-'Sonde étalon'!$C$14 -> 24.2 | T14: =D14-Q14 -> -0.14 | U14: =E14-Q14 -> -0.14 | V14: =F14-Q14 -> -0.26 | W14: =G14-Q14 -> -0.14 | X14: =H14-Q14 -> -0.2 | Y14: =I14-Q14 -> -0.2 | Z14: =J14-Q14 -> 0.05 | AA14: =K14-Q14 -> -0.07 | AB14: =L14-Q14 -> -0.32 | AC14: =M14-Q14 -> 2.6 | AF14: =D14-$T$3 -> 24.211831 | AG14: =E14-$U$3 -> 24.280563 | AH14: =F14-$V$3 -> 24.181408 | AI14: =G14-$W$3 -> 24.275634 | AJ14: =H14-$X$3 -> 24.233803 | AK14: =I14-$Y$3 -> 24.138169 | AL14: =J14-$Z$3 -> 24.274789 | AM14: =K14-$AA$3 -> 24.220141 | AN14: =L14-$AB$3 -> 24.228732 | AO14: =M14-$AC$3 -> 24.191831 | AR14: =AF14-Q14 -> 0.011830986 | AS14: =AG14-Q14 -> 0.08056338 | AT14: =AH14-Q14 -> -0.018591549 | AU14: =AI14-Q14 -> 0.075633803 | AV14: =AJ14-Q14 -> 0.033802817 | AW14: =AK14-Q14 -> -0.061830986 | AX14: =AL14-Q14 -> 0.074788732 | AY14: =AM14-Q14 -> 0.020140845 | AZ14: =AN14-Q14 -> 0.028732394 | BA14: =AO14-Q14 -> -0.0081690141
A15: 12 | B15: 43551 | C15: 0.66678241 | D15: 24.06 | E15: 24.06 | F15: 23.94 | G15: 24 | H15: 24 | I15: 24 | J15: 24.25 | K15: 24.13 | L15: 23.88 | M15: 26.8 | N15: 18 | P15: 24.02 | Q15: =P15-'Sonde étalon'!$C$14 -> 24.19 | T15: =D15-Q15 -> -0.13 | U15: =E15-Q15 -> -0.13 | V15: =F15-Q15 -> -0.25 | W15: =G15-Q15 -> -0.19 | X15: =H15-Q15 -> -0.19 | Y15: =I15-Q15 -> -0.19 | Z15: =J15-Q15 -> 0.06 | AA15: =K15-Q15 -> -0.06 | AB15: =L15-Q15 -> -0.31 | AC15: =M15-Q15 -> 2.61 | AF15: =D15-$T$3 -> 24.211831 | AG15: =E15-$U$3 -> 24.280563 | AH15: =F15-$V$3 -> 24.181408 | AI15: =G15-$W$3 -> 24.215634 | AJ15: =H15-$X$3 -> 24.233803 | AK15: =I15-$Y$3 -> 24.138169 | AL15: =J15-$Z$3 -> 24.274789 | AM15: =K15-$AA$3 -> 24.220141 | AN15: =L15-$AB$3 -> 24.228732 | AO15: =M15-$AC$3 -> 24.191831 | AR15: =AF15-Q15 -> 0.021830986 | AS15: =AG15-Q15 -> 0.09056338 | AT15: =AH15-Q15 -> -0.0085915493 | AU15: =AI15-Q15 -> 0.025633803 | AV15: =AJ15-Q15 -> 0.043802817 | AW15: =AK15-Q15 -> -0.051830986 | AX15: =AL15-Q15 -> 0.084788732 | AY15: =AM15-Q15 -> 0.030140845 | AZ15: =AN15-Q15 -> 0.038732394 | BA15: =AO15-Q15 -> 0.0018309859
A16: 13 | B16: 43551 | C16: 0.66747685 | D16: 24.13 | E16: 24.06 | F16: 24 | G16: 24.06 | H16: 24 | I16: 24.06 | J16: 24.25 | K16: 24.13 | L16: 23.88 | M16: 26.8 | N16: 18 | P16: 24 | Q16: =P16-'Sonde étalon'!$C$14 -> 24.17 | T16: =D16-Q16 -> -0.04 | U16: =E16-Q16 -> -0.11 | V16: =F16-Q16 -> -0.17 | W16: =G16-Q16 -> -0.11 | X16: =H16-Q16 -> -0.17 | Y16: =I16-Q16 -> -0.11 | Z16: =J16-Q16 -> 0.08 | AA16: =K16-Q16 -> -0.04 | AB16: =L16-Q16 -> -0.29 | AC16: =M16-Q16 -> 2.63 | AF16: =D16-$T$3 -> 24.281831 | AG16: =E16-$U$3 -> 24.280563 | AH16: =F16-$V$3 -> 24.241408 | AI16: =G16-$W$3 -> 24.275634 | AJ16: =H16-$X$3 -> 24.233803 | AK16: =I16-$Y$3 -> 24.198169 | AL16: =J16-$Z$3 -> 24.274789 | AM16: =K16-$AA$3 -> 24.220141 | AN16: =L16-$AB$3 -> 24.228732 | AO16: =M16-$AC$3 -> 24.191831 | AR16: =AF16-Q16 -> 0.11183099 | AS16: =AG16-Q16 -> 0.11056338 | AT16: =AH16-Q16 -> 0.071408451 | AU16: =AI16-Q16 -> 0.1056338 | AV16: =AJ16-Q16 -> 0.063802817 | AW16: =AK16-Q16 -> 0.028169014 | AX16: =AL16-Q16 -> 0.10478873 | AY16: =AM16-Q16 -> 0.050140845 | AZ16: =AN16-Q16 -> 0.058732394 | BA16: =AO16-Q16 -> 0.021830986
A17: 14 | B17: 43551 | C17: 0.6681713 | D17: 24.13 | E17: 24.13 | F17: 24 | G17: 24.06 | H17: 24 | I17: 24.06 | J17: 24.25 | K17: 24.13 | L17: 23.94 | M17: 26.8 | N17: 18 | P17: 24.02 | Q17: =P17-'Sonde étalon'!$C$14 -> 24.19 | T17: =D17-Q17 -> -0.06 | U17: =E17-Q17 -> -0.06 | V17: =F17-Q17 -> -0.19 | W17: =G17-Q17 -> -0.13 | X17: =H17-Q17 -> -0.19 | Y17: =I17-Q17 -> -0.13 | Z17: =J17-Q17 -> 0.06 | AA17: =K17-Q17 -> -0.06 | AB17: =L17-Q17 -> -0.25 | AC17: =M17-Q17 -> 2.61 | AF17: =D17-$T$3 -> 24.281831 | AG17: =E17-$U$3 -> 24.350563 | AH17: =F17-$V$3 -> 24.241408 | AI17: =G17-$W$3 -> 24.275634 | AJ17: =H17-$X$3 -> 24.233803 | AK17: =I17-$Y$3 -> 24.198169 | AL17: =J17-$Z$3 -> 24.274789 | AM17: =K17-$AA$3 -> 24.220141 | AN17: =L17-$AB$3 -> 24.288732 | AO17: =M17-$AC$3 -> 24.191831 | AR17: =AF17-Q17 -> 0.091830986 | AS17: =AG17-Q17 -> 0.16056338 | AT17: =AH17-Q17 -> 0.051408451 | AU17: =AI17-Q17 -> 0.085633803 | AV17: =AJ17-Q17 -> 0.043802817 | AW17: =AK17-Q17 -> 0.0081690141 | AX17: =AL17-Q17 -> 0.084788732 | AY17: =AM17-Q17 -> 0.030140845 | AZ17: =AN17-Q17 -> 0.098732394 | BA17: =AO17-Q17 -> 0.0018309859
... A76: 73 | B76: 43551 | C76: 0.70914352 | D76: 24.25 | E76: 24.19 | F76: 24.19 | G76: 24.19 | H76: 24.19 | I76: 24.31 | J76: 24.38 | K76: 24.38 | L76: 24.06 | M76: 27.2 | N76: 15 | P76: 24.29 | Q76: =P76-'Sonde étalon'!$C$14 -> 24.46 | T76: =D76-Q76 -> -0.21 | U76: =E76-Q76 -> -0.27 | V76: =F76-Q76 -> -0.27 | W76: =G76-Q76 -> -0.27 | X76: =H76-Q76 -> -0.27 | Y76: =I76-Q76 -> -0.15 | Z76: =J76-Q76 -> -0.08 | AA76: =K76-Q76 -> -0.08 | AB76: =L76-Q76 -> -0.4 | AC76: =M76-Q76 -> 2.74 | AF76: =D76-$T$3 -> 24.401831 | AG76: =E76-$U$3 -> 24.410563 | AH76: =F76-$V$3 -> 24.431408 | AI76: =G76-$W$3 -> 24.405634 | AJ76: =H76-$X$3 -> 24.423803 | AK76: =I76-$Y$3 -> 24.448169 | AL76: =J76-$Z$3 -> 24.404789 | AM76: =K76-$AA$3 -> 24.470141 | AN76: =L76-$AB$3 -> 24.408732 | AO76: =M76-$AC$3 -> 24.591831 | AR76: =AF76-Q76 -> -0.058169014 | AS76: =AG76-Q76 -> -0.04943662 | AT76: =AH76-Q76 -> -0.028591549 | AU76: =AI76-Q76 -> -0.054366197 | AV76: =AJ76-Q76 -> -0.036197183 | AW76: =AK76-Q76 -> -0.011830986 | AX76: =AL76-Q76 -> -0.055211268 | AY76: =AM76-Q76 -> 0.010140845 | AZ76: =AN76-Q76 -> -0.051267606 | BA76: =AO76-Q76 -> 0.13183099

Sheet Résultats
B4: -20°C | C4: E | D4: U | F4: 5°C | G4: E | H4: U | J4: 20°C | K4: E | L4: U
B5: MIL | C5: ='Relevés -20°C'!$R$3 -> -0.077416667 | D5: ='Relevés -20°C'!$AN$4 *2 -> 0.088063093 | F5: MIL | G5: ='Relevés 5°C'!$R$3 -> -0.1091 | H5: ='Relevés 5°C'!$AN$4 *2 -> 0.088857084 | J5: MIL | K5: ='Relevés 20°C'!$T$3 -> -0.15183099 | L5: ='Relevés 20°C'!$AR$4 *2 -> 0.088519762
B6: HGAV | C6: ='Relevés -20°C'!$S$3 -> -0.086833333 | D6: ='Relevés -20°C'!$AO$4 *2 -> 0.088030798 | F6: HGAV | G6: ='Relevés 5°C'!$S$3 -> -0.23705 | H6: ='Relevés 5°C'!$AO$4 *2 -> 0.089404594 | J6: HGAV | K6: ='Relevés 20°C'!$U$3 -> -0.22056338 | L6: ='Relevés 20°C'!$AS$4 *2 -> 0.089524713
B7: HGAR | C7: ='Relevés -20°C'!$T$3 -> 0.0205 | D7: ='Relevés -20°C'!$AP$4 *2 -> 0.08805239 | F7: HGAR | G7: ='Relevés 5°C'!$T$3 -> -0.0899 | H7: ='Relevés 5°C'!$AP$4 *2 -> 0.088849143 | J7: HGAR | K7: ='Relevés 20°C'!$V$3 -> -0.24140845 | L7: ='Relevés 20°C'!$AT$4 *2 -> 0.088424231
B8: HDAV | C8: ='Relevés -20°C'!$U$3 -> -0.023833333 | D8: ='Relevés -20°C'!$AQ$4 *2 -> 0.088022906 | F8: HDAV | G8: ='Relevés 5°C'!$U$3 -> -0.3436 | H8: ='Relevés 5°C'!$AQ$4 *2 -> 0.090781976 | J8: HDAV | K8: ='Relevés 20°C'!$W$3 -> -0.2156338 | L8: ='Relevés 20°C'!$AU$4 *2 -> 0.088690912
B9: HDAR | C9: ='Relevés -20°C'!$V$3 -> -0.16258333 | D9: ='Relevés -20°C'!$AR$4 *2 -> 0.088038279 | F9: HDAR | G9: ='Relevés 5°C'!$V$3 -> -0.386 | H9: ='Relevés 5°C'!$AR$4 *2 -> 0.088320224 | J9: HDAR | K9: ='Relevés 20°C'!$X$3 -> -0.23380282 | L9: ='Relevés 20°C'!$AV$4 *2 -> 0.088260308
B10: BGAV | C10: ='Relevés -20°C'!$W$3 -> -0.16816667 | D10: ='Relevés -20°C'!$AS$4 *2 -> 0.088057204 | F10: BGAV | G10: ='Relevés 5°C'!$W$3 -> -0.362 | H10: ='Relevés 5°C'!$AS$4 *2 -> 0.098049826 | J10: BGAV | K10: ='Relevés 20°C'!$Y$3 -> -0.13816901 | L10: ='Relevés 20°C'!$AW$4 *2 -> 0.088458824
B11: BGAR | C11: ='Relevés -20°C'!$X$3 -> 0.22208333 | D11: ='Relevés -20°C'!$AT$4 *2 -> 0.088043815 | F11: BGAR | G11: ='Relevés 5°C'!$X$3 -> 0.03555 | H11: ='Relevés 5°C'!$AT$4 *2 -> 0.089907342 | J11: BGAR | K11: ='Relevés 20°C'!$Z$3 -> -0.024788732 | L11: ='Relevés 20°C'!$AX$4 *2 -> 0.088727317
B12: BDAV | C12: ='Relevés -20°C'!$Y$3 -> 0.155 | D12: ='Relevés -20°C'!$AU$4 *2 -> 0.088037167 | F12: BDAV | G12: ='Relevés 5°C'!$Y$3 -> -0.0948 | H12: ='Relevés 5°C'!$AU$4 *2 -> 0.089186264 | J12: BDAV | K12: ='Relevés 20°C'!$AA$3 -> -0.090140845 | L12: ='Relevés 20°C'!$AY$4 *2 -> 0.08829598
B13: BDAR | C13: ='Relevés -20°C'!$Z$3 -> -0.3185 | D13: ='Relevés -20°C'!$AV$4 *2 -> 0.088045327 | F13: BDAR | G13: ='Relevés 5°C'!$Z$3 -> -0.63515 | H13: ='Relevés 5°C'!$AV$4 *2 -> 0.092933429 | J13: BDAR | K13: ='Relevés 20°C'!$AB$3 -> -0.34873239 | L13: ='Relevés 20°C'!$AZ$4 *2 -> 0.088388393
J15: AMB | K15: ='Relevés 20°C'!$AC$3 -> 2.608169 | L15: ='Relevés 20°C'!$BA$4 *2 -> 0.58326835

Sheet Feuil1
A1: 43556 | B1: 0.47988426 | C1: Mesure | D1: -19.77
A2: 43556 | B2: 0.4805787 | C2: Mesure | D2: -20.05
A3: 43556 | B3: 0.48127315 | C3: Mesure | D3: -20.31
A4: 43556 | B4: 0.48196759 | C4: Mesure | D4: -20.52
A5: 43556 | B5: 0.48266204 | C5: Mesure | D5: -20.78
A6: 43556 | B6: 0.48335648 | C6: Mesure | D6: -20.97
A7: 43556 | B7: 0.48405093 | C7: Mesure | D7: -21.18
A8: 43556 | B8: 0.48474537 | C8: Mesure | D8: -21.38
A9: 43556 | B9: 0.48543981 | C9: Mesure | D9: -21.55
A10: 43556 | B10: 0.48613426 | C10: Mesure | D10: -21.72
A11: 43556 | B11: 0.4868287 | C11: Mesure | D11: -21.88
A12: 43556 | B12: 0.48752315 | C12: Mesure | D12: -22.09
... A184: 43556 | B184: 0.60640046 | C184: Mesure | D184: -25.18

Sheet Feuil2
A1: 43556 | B1: 0.47988426 | C1: Mesure | D1: -19.77
A2: 43556 | B2: 0.4805787 | C2: Mesure | D2: -20.05
A3: 43556 | B3: 0.48127315 | C3: Mesure | D3: -20.31
A4: 43556 | B4: 0.48196759 | C4: Mesure | D4: -20.52
A5: 43556 | B5: 0.48266204 | C5: Mesure | D5: -20.78
A6: 43556 | B6: 0.48335648 | C6: Mesure | D6: -20.97
A7: 43556 | B7: 0.48405093 | C7: Mesure | D7: -21.18
A8: 43556 | B8: 0.48474537 | C8: Mesure | D8: -21.38
A9: 43556 | B9: 0.48543981 | C9: Mesure | D9: -21.55
A10: 43556 | B10: 0.48613426 | C10: Mesure | D10: -21.72
A11: 43556 | B11: 0.4868287 | C11: Mesure | D11: -21.88
A12: 43556 | B12: 0.48752315 | C12: Mesure | D12: -22.09
... A183: 43556 | B183: 0.60640046 | C183: Mesure | D183: -25.18

Sheet Feuil3
B1: -20°C | D1: 5°C | F1: 20°C
A2: ° C | B2: E | C2: U | D2: E | E2: U | F2: E | G2: U
A3: MIL | B3: ='Relevés -20°C'!$R$3 -> -0.077416667 | C3: ='Relevés -20°C'!$AN$4 *2 -> 0.088063093 | D3: ='Relevés 5°C'!$R$3 -> -0.1091 | E3: ='Relevés 5°C'!$AN$4 *2 -> 0.088857084 | F3: ='Relevés 20°C'!$T$3 -> -0.15183099 | G3: ='Relevés 20°C'!$AR$4 *2 -> 0.088519762
A4: HGAV | B4: ='Relevés -20°C'!$S$3 -> -0.086833333 | C4: ='Relevés -20°C'!$AO$4 *2 -> 0.088030798 | D4: ='Relevés 5°C'!$S$3 -> -0.23705 | E4: ='Relevés 5°C'!$AO$4 *2 -> 0.089404594 | F4: ='Relevés 20°C'!$U$3 -> -0.22056338 | G4: ='Relevés 20°C'!$AS$4 *2 -> 0.089524713
A5: HGAR | B5: ='Relevés -20°C'!$T$3 -> 0.0205 | C5: ='Relevés -20°C'!$AP$4 *2 -> 0.08805239 | D5: ='Relevés 5°C'!$T$3 -> -0.0899 | E5: ='Relevés 5°C'!$AP$4 *2 -> 0.088849143 | F5: ='Relevés 20°C'!$V$3 -> -0.24140845 | G5: ='Relevés 20°C'!$AT$4 *2 -> 0.088424231
A6: HDAV | B6: ='Relevés -20°C'!$U$3 -> -0.023833333 | C6: ='Relevés -20°C'!$AQ$4 *2 -> 0.088022906 | D6: ='Relevés 5°C'!$U$3 -> -0.3436 | E6: ='Relevés 5°C'!$AQ$4 *2 -> 0.090781976 | F6: ='Relevés 20°C'!$W$3 -> -0.2156338 | G6: ='Relevés 20°C'!$AU$4 *2 -> 0.088690912
A7: HDAR | B7: ='Relevés -20°C'!$V$3 -> -0.16258333 | C7: ='Relevés -20°C'!$AR$4 *2 -> 0.088038279 | D7: ='Relevés 5°C'!$V$3 -> -0.386 | E7: ='Relevés 5°C'!$AR$4 *2 -> 0.088320224 | F7: ='Relevés 20°C'!$X$3 -> -0.23380282 | G7: ='Relevés 20°C'!$AV$4 *2 -> 0.088260308
